Workbook

Sheet Summary 
B2: Denim | U2: WASHING
B3: Month | C3: Description | D3: GF | G3: LT01 | H3: LT02 | I3: FF | L3: LT01 | M3: LT02 | N3: SF | Q3: LT01 | R3: LT02 | S3: Consumption | T3: Cnsmptn% | U3: Description | V3: WASHING BUILDING | Y3: Cnsmptn% | Z3: GF | AA3: FF
D4: LT1 | E4: LT2 | F4: Total | G4: OT Hrs | I4: LT1 | J4: LT2 | K4: Total | L4: OT Hrs | N4: LT1 | O4: LT2 | P4: Total | Q4: OT Hrs | V4: GF | W4: FF | X4: Grand Total | Z4: OT hrs
B5: 45863 | C5: Lights | D5: ='LT GF'!L37 -> 2555 | E5: ='LT GF'!V37 -> 2373 | F5: =D5+E5 -> 4928 | I5: ='LT FF'!N37 -> 333 | J5: ='LT FF'!X37 -> 94 | K5: =I5+J5 -> 427 | N5: ='LT 2F'!P37 -> 7323 | O5: ='LT 2F'!Z37 -> 2731 | P5: =N5+O5 -> 10054 | S5: =F5+K5+P5 -> 15409 | T5: =S5/$S$12 -> 0.29375095 | U5: Lights | V5: ='LT-Wshng'!Q37 -> 822 | W5: ='LT-Wshng'!W37 -> 0 | X5: =V5+W5 -> 822 | Y5: =X5/$X$12 -> 0.018841543
C6: Exhaust Fan | D6: ='LT GF'!H37 -> 5201 | F6: =D6+E6 -> 5201 | I6: ='LT FF'!J37 -> 1963 | K6: =I6+J6 -> 1963 | N6: ='LT 2F'!L37 -> 5311 | P6: =N6+O6 -> 5311 | S6: =F6+K6+P6 -> 12475 | T6: =S6/$S$12 -> 0.23781836 | U6: Exhaust Fan | V6: ='LT-Wshng'!O37 -> 6511 | W6: 0 | X6: =V6+W6 -> 6511 | Y6: =X6/$X$12 -> 0.14924244
C7: HVAC | D7: ='LT GF'!J37 -> 258 | E7: ='LT GF'!T37 -> 1732 | F7: =D7+E7 -> 1990 | I7: ='LT FF'!L37 -> 263 | J7: ='LT FF'!V37 -> 2034 | K7: =I7+J7 -> 2297 | N7: ='LT 2F'!N37 -> 277 | O7: ='LT 2F'!X37 -> 154 | P7: =N7+O7 -> 431 | S7: =F7+K7+P7 -> 4718 | T7: =S7/$S$12 -> 0.089942047 | U7: HVAC | V7: 0 | W7: 0 | X7: =V7+W7 -> 0 | Y7: =X7/$X$12 -> 0
C8: Machines | D8: ='LT GF'!F37 -> 0 | E8: ='LT GF'!R37 -> 0 | F8: =D8+E8 -> 0 | I8: ='LT FF'!H37 -> 6477 | J8: ='LT FF'!T37 -> 1708 | K8: =I8+J8 -> 8185 | N8: ='LT 2F'!J37 -> 1334 | O8: ='LT 2F'!V37 -> 0 | P8: =N8+O8 -> 1334 | S8: =F8+K8+P8 -> 9519 | T8: =S8/$S$12 -> 0.18146637 | U8: Machines | V8: ='LT-Wshng'!E37-'Summary '!V5-V6-V7 -> 23199 | W8: ='LT-Wshng'!U37-W5-W6-W7-W9-W10-W11 -> 13095 | X8: =V8+W8 -> 36294 | Y8: =X8/$X$12 -> 0.83191602
C9: Office | D9: ='LT GF'!N37 -> 23 | E9: ='LT GF'!X37 -> 261 | F9: =D9+E9 -> 284 | I9: ='LT FF'!P37 -> 4261 | J9: ='LT FF'!Z37 -> 4314 | K9: =I9+J9 -> 8575 | N9: ='LT 2F'!R37 -> 1322 | O9: ='LT 2F'!X37 -> 154 | P9: =N9+O9 -> 1476 | S9: =F9+K9+P9 -> 10335 | T9: =S9/$S$12 -> 0.19702227 | U9: Office | X9: =V9+W9 -> 0 | Y9: =X9/$X$12 -> 0
F10: =D10+E10 -> 0 | K10: =I10+J10 -> 0 | P10: =N10+O10 -> 0 | S10: =F10+K10+P10 -> 0 | U10: Laser 1 | W10: ='LT-Wshng'!AC37 -> 0 | X10: =V10+W10 -> 0 | Y10: =X10/$X$12 -> 0
F11: =D11+E11 -> 0 | K11: =I11+J11 -> 0 | P11: =N11+O11 -> 0 | S11: =F11+K11+P11 -> 0 | U11: Laser 2 | W11: ='LT-Wshng'!AE37 -> 0 | X11: =V11+W11 -> 0 | Y11: =X11/$X$12 -> 0
C12: Sum | F12: =SUM(F5:F11) -> 12403 | K12: =SUM(K5:K11) -> 21447 | P12: =SUM(P5:P11) -> 18606 | S12: =F12+K12+P12 -> 52456 | T12: =SUM(T5:T11) -> 1 | V12: =SUM(V5:V11) -> 30532 | W12: =SUM(W5:W11) -> 13095 | X12: =V12+W12 -> 43627
B13: 45894 | C13: Lights | D13: ='LT GF'!L70 -> 2612 | E13: ='LT GF'!V70 -> 2038 | F13: =D13+E13 -> 4650 | I13: ='LT FF'!N70 -> 362 | J13: ='LT FF'!X70 -> 239 | K13: =I13+J13 -> 601 | N13: ='LT 2F'!P70 -> 7496 | O13: ='LT 2F'!Z70 -> 2553 | P13: =N13+O13 -> 10049 | S13: =F13+K13+P13 -> 15300 | T13: =S13/$S$20 -> 0.27094992 | U13: Lights | V13: ='LT-Wshng'!Q70 -> 3426 | W13: ='LT-Wshng'!W45 -> 113 | X13: =V13+W13 -> 3539 | Y13: =X13/$X$20 -> 0.066734551
C14: Exhaust Fan | D14: ='LT GF'!H70 -> 5732 | F14: =D14+E14 -> 5732 | I14: ='LT FF'!J70 -> 1954 | K14: =I14+J14 -> 1954 | N14: ='LT 2F'!L70 -> 5273 | P14: =N14+O14 -> 5273 | S14: =F14+K14+P14 -> 12959 | T14: =S14/$S$20 -> 0.22949281 | U14: Exhaust Fan | V14: ='LT-Wshng'!O70 -> 6283 | W14: 0 | X14: =V14+W14 -> 6283 | Y14: =X14/$X$20 -> 0.11847787
C15: HVAC | D15: ='LT GF'!J70 -> 518 | E15: ='LT GF'!T70 -> 1913 | F15: =D15+E15 -> 2431 | I15: ='LT FF'!L70 -> 257 | J15: ='LT FF'!V70 -> 1947 | K15: =I15+J15 -> 2204 | N15: ='LT 2F'!N70 -> 261 | O15: ='LT 2F'!X70 -> 122 | P15: =N15+O15 -> 383 | S15: =F15+K15+P15 -> 5018 | T15: =S15/$S$20 -> 0.08886449 | U15: HVAC | V15: 0 | W15: 0 | X15: =V15+W15 -> 0 | Y15: =X15/$X$20 -> 0
C16: Machines | D16: ='LT GF'!F70 -> 0 | E16: ='LT GF'!R70 -> 288 | F16: =D16+E16 -> 288 | I16: ='LT FF'!H70 -> 6827 | J16: ='LT FF'!T70 -> 1895 | K16: =I16+J16 -> 8722 | N16: ='LT 2F'!J70 -> 1455 | O16: ='LT 2F'!V70 -> 0 | P16: =N16+O16 -> 1455 | S16: =F16+K16+P16 -> 10465 | T16: =S16/$S$20 -> 0.1853262 | U16: Machines | V16: ='LT-Wshng'!E70-'Summary '!V13-V14-V15 -> 27157 | W16: ='LT-Wshng'!U70-W13-W14-W15-W17-W18-W19 -> 11529 | X16: =V16+W16 -> 38686 | Y16: =X16/$X$20 -> 0.72949784
C17: Office | D17: ='LT GF'!N70 -> 47 | E17: ='LT GF'!X70 -> 311 | F17: =D17+E17 -> 358 | I17: ='LT FF'!P70 -> 5688 | J17: ='LT FF'!Z70 -> 5569 | K17: =I17+J17 -> 11257 | N17: ='LT 2F'!R70 -> 989 | O17: ='LT 2F'!X70 -> 122 | P17: =N17+O17 -> 1111 | S17: =F17+K17+P17 -> 12726 | T17: =S17/$S$20 -> 0.22536658 | U17: Office | X17: =V17+W17 -> 0 | Y17: =X17/$X$20 -> 0
F18: =D18+E18 -> 0 | K18: =I18+J18 -> 0 | P18: =N18+O18 -> 0 | S18: =F18+K18+P18 -> 0 | U18: Laser 1 | W18: ='LT-Wshng'!AC70 -> 2257 | X18: =V18+W18 -> 2257 | Y18: =X18/$X$20 -> 0.042560012
F19: =D19+E19 -> 0 | K19: =I19+J19 -> 0 | P19: =N19+O19 -> 0 | S19: =F19+K19+P19 -> 0 | U19: Laser 2 | W19: ='LT-Wshng'!AE70 -> 2266 | X19: =V19+W19 -> 2266 | Y19: =X19/$X$20 -> 0.042729724
C20: Sum | F20: =SUM(F13:F19) -> 13459 | K20: =SUM(K13:K19) -> 24738 | P20: =SUM(P13:P19) -> 18271 | S20: =F20+K20+P20 -> 56468 | T20: =SUM(T13:T19) -> 1 | V20: =SUM(V13:V19) -> 36866 | W20: =SUM(W13:W19) -> 16165 | X20: =V20+W20 -> 53031
B21: 45925 | C21: Lights | D21: ='LT GF'!L102 -> 2794 | E21: ='LT GF'!V102 -> 2205 | F21: =D21+E21 -> 4999 | I21: ='LT FF'!N102 -> 274 | J21: ='LT FF'!X102 -> 172 | K21: =I21+J21 -> 446 | N21: ='LT 2F'!P102 -> 7222 | O21: ='LT 2F'!Z102 -> 2535 | P21: =N21+O21 -> 9757 | S21: =F21+K21+P21 -> 15202 | T21: =S21/$S$28 -> 0.24884596 | U21: Lights | V21: ='LT-Wshng'!Q102 -> 3444 | W21: ='LT-Wshng'!W102 -> 2876 | X21: =V21+W21 -> 6320 | Y21: =X21/$X$28 -> 0.11116583
C22: Exhaust Fan | D22: ='LT GF'!H102 -> 5176 | F22: =D22+E22 -> 5176 | I22: ='LT FF'!J102 -> 2165 | K22: =I22+J22 -> 2165 | N22: ='LT 2F'!L102 -> 5333 | P22: =N22+O22 -> 5333 | S22: =F22+K22+P22 -> 12674 | T22: =S22/$S$28 -> 0.2074644 | U22: Exhaust Fan | V22: ='LT-Wshng'!O102 -> 6093 | W22: 0 | X22: =V22+W22 -> 6093 | Y22: =X22/$X$28 -> 0.10717301
C23: HVAC | D23: ='LT GF'!J102 -> 662 | E23: ='LT GF'!T102 -> 2383 | F23: =D23+E23 -> 3045 | I23: ='LT FF'!L102 -> 311 | J23: ='LT FF'!V102 -> 1860 | K23: =I23+J23 -> 2171 | N23: ='LT 2F'!N102 -> 288 | O23: ='LT 2F'!X102 -> 141 | P23: =N23+O23 -> 429 | S23: =F23+K23+P23 -> 5645 | T23: =S23/$S$28 -> 0.092404649 | U23: HVAC | V23: 0 | W23: 0 | X23: =V23+W23 -> 0 | Y23: =X23/$X$28 -> 0
C24: Machines | D24: ='LT GF'!F102 -> 0 | E24: ='LT GF'!R102 -> 1735 | F24: =D24+E24 -> 1735 | I24: ='LT FF'!H102 -> 6888 | J24: ='LT FF'!T102 -> 2585 | K24: =I24+J24 -> 9473 | N24: ='LT 2F'!J102 -> 2097 | O24: ='LT 2F'!V102 -> 0 | P24: =N24+O24 -> 2097 | S24: =F24+K24+P24 -> 13305 | T24: =S24/$S$28 -> 0.21779342 | U24: Machines | V24: ='LT-Wshng'!E102-'Summary '!V21-V22-V23 -> 31175 | W24: ='LT-Wshng'!U102-W21-W22-W23-W25-W26-W27 -> 8672 | X24: =V24+W24 -> 39847 | Y24: =X24/$X$28 -> 0.70089003
C25: Office | D25: ='LT GF'!N102 -> 40 | E25: ='LT GF'!X102 -> 333 | F25: =D25+E25 -> 373 | I25: ='LT FF'!P102 -> 6390 | J25: ='LT FF'!Z102 -> 6404 | K25: =I25+J25 -> 12794 | N25: ='LT 2F'!R102 -> 956 | O25: ='LT 2F'!X102 -> 141 | P25: =N25+O25 -> 1097 | S25: =F25+K25+P25 -> 14264 | T25: =S25/$S$28 -> 0.23349157 | U25: Office | X25: =V25+W25 -> 0 | Y25: =X25/$X$28 -> 0
F26: =D26+E26 -> 0 | K26: =I26+J26 -> 0 | P26: =N26+O26 -> 0 | S26: =F26+K26+P26 -> 0 | U26: Laser 1 | W26: ='LT-Wshng'!AC102 -> 2265 | X26: =V26+W26 -> 2265 | Y26: =X26/$X$28 -> 0.039840287
F27: =D27+E27 -> 0 | K27: =I27+J27 -> 0 | P27: =N27+O27 -> 0 | S27: =F27+K27+P27 -> 0 | U27: Laser 2 | W27: ='LT-Wshng'!AE102 -> 2327 | X27: =V27+W27 -> 2327 | Y27: =X27/$X$28 -> 0.040930838
C28: Sum | F28: =SUM(F21:F27) -> 15328 | K28: =SUM(K21:K27) -> 27049 | P28: =SUM(P21:P27) -> 18713 | S28: =F28+K28+P28 -> 61090 | T28: =SUM(T21:T27) -> 1 | V28: =SUM(V21:V27) -> 40712 | W28: =SUM(W21:W27) -> 16140 | X28: =V28+W28 -> 56852
B29: 45931 | C29: Lights | D29: ='LT GF'!L135 -> 3898 | E29: ='LT GF'!V135 -> 3163 | F29: =D29+E29 -> 7061 | G29: =Overtime!H37 -> 944 | H29: =Overtime!N37 -> 582 | I29: ='LT FF'!N135 -> 337 | J29: ='LT FF'!X135 -> 228 | K29: =I29+J29 -> 565 | L29: =Overtime!V37 -> 162 | M29: =Overtime!AB37 -> 241 | N29: ='LT 2F'!P135 -> 8252 | O29: ='LT 2F'!Z135 -> 3413 | P29: =N29+O29 -> 11665 | Q29: =Overtime!AJ37 -> 470 | R29: =Overtime!AP37 -> 0 | S29: =F29+K29+P29 -> 19291 | T29: =S29/$S$36 -> 0.33906915 | U29: Lights | V29: ='LT-Wshng'!Q135 -> 4496 | W29: ='LT-Wshng'!W135 -> 3150 | X29: =V29+W29 -> 7646 | Y29: =X29/$X$36 -> 0.089275498 | Z29: =Overtime!AX37 -> 652 | AA29: =Overtime!BD37 -> 363
C30: Exhaust Fan | D30: ='LT GF'!H135 -> 3266 | F30: =D30+E30 -> 3266 | G30: =Overtime!F37 -> 233 | I30: ='LT FF'!J135 -> 1311 | K30: =I30+J30 -> 1311 | L30: =Overtime!T37 -> 195 | N30: ='LT 2F'!L135 -> 5847 | P30: =N30+O30 -> 5847 | Q30: =Overtime!AH37 -> 208 | S30: =F30+K30+P30 -> 10424 | T30: =S30/$S$36 -> 0.18321791 | U30: Exhaust Fan | V30: ='LT-Wshng'!O135 -> 7007 | W30: 0 | X30: =V30+W30 -> 7007 | Y30: =X30/$X$36 -> 0.081814467 | Z30: =Overtime!AV37 -> 804
C31: HVAC | D31: ='LT GF'!J135 -> 301 | E31: ='LT GF'!T135 -> 1059 | F31: =D31+E31 -> 1360 | I31: ='LT FF'!L135 -> 408 | J31: ='LT FF'!V135 -> 2107 | K31: =I31+J31 -> 2515 | N31: ='LT 2F'!N135 -> 352 | O31: ='LT 2F'!X135 -> 141 | P31: =N31+O31 -> 493 | S31: =F31+K31+P31 -> 4368 | T31: =S31/$S$36 -> 0.076774352 | U31: HVAC | V31: 0 | W31: 0 | X31: =V31+W31 -> 0 | Y31: =X31/$X$36 -> 0
C32: Machines | D32: ='LT GF'!F135 -> 0 | E32: ='LT GF'!R135 -> 2029 | F32: =D32+E32 -> 2029 | G32: =Overtime!L37 -> 88 | I32: ='LT FF'!H135 -> 3983 | J32: ='LT FF'!T135 -> 1542 | K32: =I32+J32 -> 5525 | L32: =Overtime!R37 -> 144 | M32: =Overtime!Z37 -> 200 | N32: ='LT 2F'!J135 -> 1308 | O32: ='LT 2F'!V135 -> 0 | P32: =N32+O32 -> 1308 | Q32: =Overtime!AF37 -> 196 | R32: =Overtime!AN37 -> 129 | S32: =F32+K32+P32 -> 8862 | T32: =S32/$S$36 -> 0.15576335 | U32: Machines | V32: ='LT-Wshng'!E135-'Summary '!V29-V30-V31 -> 56910 | W32: ='LT-Wshng'!U135-W29-W30-W31-W33-W34-W35 -> 8123 | X32: =V32+W32 -> 65033 | Y32: =X32/$X$36 -> 0.75933213
C33: Office | D33: ='LT GF'!N135 -> 54 | E33: ='LT GF'!X135 -> 250 | F33: =D33+E33 -> 304 | I33: ='LT FF'!P135 -> 5665 | J33: ='LT FF'!Z135 -> 5611 | K33: =I33+J33 -> 11276 | N33: ='LT 2F'!R135 -> 2228 | O33: ='LT 2F'!X135 -> 141 | P33: =N33+O33 -> 2369 | S33: =F33+K33+P33 -> 13949 | T33: =S33/$S$36 -> 0.24517524 | U33: Office | X33: =V33+W33 -> 0 | Y33: =X33/$X$36 -> 0
F34: =D34+E34 -> 0 | K34: =I34+J34 -> 0 | P34: =N34+O34 -> 0 | S34: =F34+K34+P34 -> 0 | U34: Laser 1 | W34: ='LT-Wshng'!AC135 -> 3009 | X34: =V34+W34 -> 3009 | Y34: =X34/$X$36 -> 0.035133399
C35: Main | F35: =D35+E35 -> 0 | G35: =Overtime!D37 -> 2239 | H35: =Overtime!J37 -> 818 | K35: =I35+J35 -> 0 | L35: =Overtime!P37 -> 868 | M35: =Overtime!X37 -> 749 | P35: =N35+O35 -> 0 | Q35: =Overtime!AD37 -> 1357 | R35: =Overtime!AL37 -> 1059 | S35: =F35+K35+P35 -> 0 | U35: Laser 2 | W35: ='LT-Wshng'!AE135 -> 2950 | X35: =V35+W35 -> 2950 | Y35: =X35/$X$36 -> 0.034444509 | Z35: =Overtime!AR37 -> 8037 | AA35: =Overtime!BB37 -> 1382
C36: Sum | F36: =SUM(F29:F35) -> 14020 | G36: =G35+H35 -> 3057 | K36: =SUM(K29:K35) -> 21192 | L36: =L35+M35 -> 1617 | P36: =SUM(P29:P35) -> 21682 | Q36: =Q35+R35 -> 2416 | S36: =F36+K36+P36 -> 56894 | T36: =SUM(T29:T35) -> 1 | V36: =SUM(V29:V35) -> 68413 | W36: =SUM(W29:W35) -> 17232 | X36: =V36+W36 -> 85645 | Z36: =Z35+AA35 -> 9419
B37: 45962 | C37: Lights | D37: ='LT GF'!L168 -> 3710 | E37: ='LT GF'!V168 -> 3164 | F37: =D37+E37 -> 6874 | G37: =Overtime!H45 -> 80 | H37: =Overtime!N45 -> 23 | I37: ='LT FF'!L168 -> 344 | J37: ='LT FF'!V168 -> 1972 | K37: =I37+J37 -> 2316 | L37: =Overtime!V45 -> 0 | M37: =Overtime!AB45 -> 2 | N37: ='LT 2F'!L168 -> 5179 | O37: ='LT 2F'!V168 -> 0 | P37: =N37+O37 -> 5179 | Q37: =Overtime!AJ45 -> 0 | R37: =Overtime!AP45 -> 0 | S37: =F37+K37+P37 -> 14369 | T37: =S37/$S$44 -> 0.52323629 | U37: Lights | V37: ='LT-Wshng'!Q168 -> 4046 | W37: ='LT-Wshng'!W168 -> 2315 | X37: =V37+W37 -> 6361 | Y37: =X37/$X$44 -> 0.3927028 | Z37: =Overtime!AX45 -> 0 | AA37: =Overtime!BD45 -> 0
C38: Exhaust Fan | D38: ='LT GF'!H168 -> 605 | F38: =D38+E38 -> 605 | G38: =Overtime!F45 -> 8 | I38: ='LT FF'!H168 -> 650 | K38: =I38+J38 -> 650 | L38: =Overtime!T45 -> 0 | N38: ='LT 2F'!H168 -> 538 | P38: =N38+O38 -> 538 | Q38: =Overtime!AH45 -> 0 | S38: =F38+K38+P38 -> 1793 | T38: =S38/$S$44 -> 0.065290742 | U38: Exhaust Fan | V38: ='LT-Wshng'!O168 -> 2249 | W38: 0 | X38: =V38+W38 -> 2249 | Y38: =X38/$X$44 -> 0.1388443 | Z38: =Overtime!AV45 -> 0
C39: HVAC | D39: ='LT GF'!J168 -> 23 | E39: ='LT GF'!T168 -> 206 | F39: =D39+E39 -> 229 | I39: ='LT FF'!J168 -> 203 | J39: ='LT FF'!T168 -> 341 | K39: =I39+J39 -> 544 | N39: ='LT 2F'!J168 -> 266 | O39: ='LT 2F'!T168 -> 94 | P39: =N39+O39 -> 360 | S39: =F39+K39+P39 -> 1133 | T39: =S39/$S$44 -> 0.04125734 | U39: HVAC | V39: 0 | W39: 0 | X39: =V39+W39 -> 0 | Y39: =X39/$X$44 -> 0
C40: Machines | D40: 0 | E40: ='LT GF'!R168 -> 1959 | F40: =D40+E40 -> 1959 | G40: =Overtime!L45 -> 0 | I40: ='LT FF'!F168 -> 1316 | J40: ='LT FF'!R168 -> 731 | K40: =I40+J40 -> 2047 | L40: =Overtime!R45 -> 0 | M40: =Overtime!Z45 -> 0 | N40: ='LT 2F'!F168 -> 2493 | O40: ='LT 2F'!R168 -> 1298 | P40: =N40+O40 -> 3791 | Q40: =Overtime!AF45 -> 0 | R40: =Overtime!AN45 -> 0 | S40: =F40+K40+P40 -> 7797 | T40: =S40/$S$44 -> 0.28392187 | U40: Machines | W40: ='LT-Wshng'!U168-W37-W38-W39-W41-W42-W43 -> 4060 | X40: =V40+W40 -> 4060 | Y40: =X40/$X$44 -> 0.25064823
C41: Office | D41: ='LT GF'!N168 -> 74 | E41: ='LT GF'!X168 -> 75 | F41: =D41+E41 -> 149 | I41: ='LT FF'!N168 -> 337 | J41: ='LT FF'!X168 -> 180 | K41: =I41+J41 -> 517 | N41: ='LT 2F'!N168 -> 492 | O41: ='LT 2F'!X168 -> 180 | P41: =N41+O41 -> 672 | S41: =F41+K41+P41 -> 1338 | T41: =S41/$S$44 -> 0.048722261 | U41: Office | X41: =V41+W41 -> 0 | Y41: =X41/$X$44 -> 0
...

Sheet SBSTN DND
B1: DENIM & WASHING SUBSTATION ENERGY ANALYZER READINGS
B2: DAY | C2: DATE | D2: INCOMING | F2: Washing GF | H2: Solar | J2: GROUND FLOOR | N2: FIRST FLOOR | R2: SECOND FLOOR | V2: WASHING GF (TEMPORARY) | X2: WASHING FF | Z2: SPARE | AB2: Sub-Station DB | AD2: SPARE | AF2: SPARE | AH2: Compressor | AJ2: kWh/Day TTL | AK2: Diff.
D3: 0 | F3: 1 | H3: 2 | J3: 3 | L3: 4 | N3: 5 | P3: 6 | R3: 7 | T3: 8 | V3: 9 | X3: 10 | Y3: 9 | Z3: 11 | AB3: 12 | AD3: 13 | AF3: 14 | AH3: 15
D4: Main ACB | F4: Washing 1600A GF | H4: Solar 1600A | J4: MPB-1-GF | L4: MPB-2-GF2 | N4: MPB-1F-LT1 | P4: MPB-1F-LT2 | R4: MPB-2F-LT1 | T4: MPB-2F-LT2 | V4: MPB-WASHING-GF | X4: MPB-WASHING-1F | Z4: Spare250A | AB4: Ac Substation/Spare100A | AD4: Spare100A | AF4: Spare63A | AH4: Compressor/Spare400A
D5: Meter Reading | E5: Daily Units (kWh) | F5: Meter Reading | G5: Daily Units (kWh) | H5: Meter Reading | I5: Daily Units (kWh) | J5: Meter Reading | K5: Daily Units (kWh) | L5: Meter Reading | M5: Daily Units (kWh) | N5: Meter Reading | O5: Daily Units (kWh) | P5: Meter Reading | Q5: Daily Units (kWh) | R5: Meter Reading | S5: Daily Units (kWh) | T5: Meter Reading | U5: Daily Units (kWh) | V5: Meter Reading | W5: Daily Units (kWh) | X5: Meter Reading | Y5: Daily Units (kWh) | Z5: Meter Reading | AA5: Daily Units (kWh) | AB5: Meter Reading | AC5: Daily Units (kWh) | AD5: Meter Reading | AE5: Daily Units (kWh) | AF5: Meter Reading | AG5: Daily Units (kWh) | AH5: Meter Reading | AI5: Daily Units (kWh)
B6: TUE | C6: 45839 | D6: 29352 | E6: =IF(D7<>"",D7-D6,"") -> 2010 | J6: 5321 | K6: =IF(J7<>"",J7-J6,"") -> 363 | M6: =IF(L7<>"",L7-L6,"") | O6: =IF(N7<>"",N7-N6,"") | Q6: =IF(P7<>"",P7-P6,"") | R6: 14413 | S6: =IF(R7<>"",R7-R6,"") -> 395 | U6: =IF(T7<>"",T7-T6,"") | V6: 17011 | W6: =IF(V7<>"",V7-V6,"") -> 1001 | X6: 625 | Y6: =IF(X7<>"",X7-X6,"") -> 310 | AJ6: =SUM(G6,K6,M6,O6,Q6,S6,U6,W6,Y6,AA6,AC6,AE6,AG6,AI6) -> 2069 | AK6: =(E6+I6)-AJ6 -> -59
B7: WED | C7: 45840 | D7: 31362 | E7: =IF(D8<>"",D8-D7,"") -> 2964 | J7: 5684 | K7: =IF(J8<>"",J8-J7,"") -> 304 | M7: =IF(L8<>"",L8-L7,"") | O7: =IF(N8<>"",N8-N7,"") | Q7: =IF(P8<>"",P8-P7,"") | R7: 14808 | S7: =IF(R8<>"",R8-R7,"") -> 480 | U7: =IF(T8<>"",T8-T7,"") | V7: 18012 | W7: =IF(V8<>"",V8-V7,"") -> 1052 | X7: 935 | Y7: =IF(X8<>"",X8-X7,"") -> 246 | AJ7: =SUM(G7,K7,M7,O7,Q7,S7,U7,W7,Y7,AA7,AC7,AE7,AG7,AI7) -> 2082 | AK7: =(E7+I7)-AJ7 -> 882
B8: THU | C8: 45841 | D8: 34326 | E8: =IF(D9<>"",D9-D8,"") -> 1533 | J8: 5988 | K8: =IF(J9<>"",J9-J8,"") -> 376 | M8: =IF(L9<>"",L9-L8,"") | O8: =IF(N9<>"",N9-N8,"") | Q8: =IF(P9<>"",P9-P8,"") | R8: 15288 | S8: =IF(R9<>"",R9-R8,"") -> 565 | U8: =IF(T9<>"",T9-T8,"") | V8: 19064 | W8: =IF(V9<>"",V9-V8,"") -> 954 | X8: 1181 | Y8: =IF(X9<>"",X9-X8,"") -> 372 | AJ8: =SUM(G8,K8,M8,O8,Q8,S8,U8,W8,Y8,AA8,AC8,AE8,AG8,AI8) -> 2267 | AK8: =(E8+I8)-AJ8 -> -734
B9: FRI | C9: 45842 | D9: 35859 | E9: =IF(D10<>"",D10-D9,"") -> 1099 | J9: 6364 | K9: =IF(J10<>"",J10-J9,"") -> 195 | M9: =IF(L10<>"",L10-L9,"") | O9: =IF(N10<>"",N10-N9,"") | Q9: =IF(P10<>"",P10-P9,"") | R9: 15853 | S9: =IF(R10<>"",R10-R9,"") -> 357 | U9: =IF(T10<>"",T10-T9,"") | V9: 20018 | W9: =IF(V10<>"",V10-V9,"") -> 894 | X9: 1553 | Y9: =IF(X10<>"",X10-X9,"") -> 251 | AJ9: =SUM(G9,K9,M9,O9,Q9,S9,U9,W9,Y9,AA9,AC9,AE9,AG9,AI9) -> 1697 | AK9: =(E9+I9)-AJ9 -> -598
B10: SAT | C10: 45843 | D10: 36958 | E10: =IF(D11<>"",D11-D10,"") -> 1021 | J10: 6559 | K10: =IF(J11<>"",J11-J10,"") -> 225 | M10: =IF(L11<>"",L11-L10,"") | O10: =IF(N11<>"",N11-N10,"") | Q10: =IF(P11<>"",P11-P10,"") | R10: 16210 | S10: =IF(R11<>"",R11-R10,"") -> 313 | U10: =IF(T11<>"",T11-T10,"") | V10: 20912 | W10: =IF(V11<>"",V11-V10,"") -> 555 | X10: 1804 | Y10: =IF(X11<>"",X11-X10,"") -> 192 | AJ10: =SUM(G10,K10,M10,O10,Q10,S10,U10,W10,Y10,AA10,AC10,AE10,AG10,AI10) -> 1285 | AK10: =(E10+I10)-AJ10 -> -264
B11: SUN | C11: 45844 | D11: 37979 | E11: =IF(D12<>"",D12-D11,"") -> 0 | J11: 6784 | K11: =IF(J12<>"",J12-J11,"") -> 0 | M11: =IF(L12<>"",L12-L11,"") | O11: =IF(N12<>"",N12-N11,"") | Q11: =IF(P12<>"",P12-P11,"") | R11: 16523 | S11: =IF(R12<>"",R12-R11,"") -> 0 | U11: =IF(T12<>"",T12-T11,"") | V11: 21467 | W11: =IF(V12<>"",V12-V11,"") -> 0 | X11: 1996 | Y11: =IF(X12<>"",X12-X11,"") -> 0 | AJ11: =SUM(G11,K11,M11,O11,Q11,S11,U11,W11,Y11,AA11,AC11,AE11,AG11,AI11) -> 0 | AK11: =(E11+I11)-AJ11 -> 0
B12: MON | C12: 45845 | D12: 37979 | E12: =IF(D13<>"",D13-D12,"") -> 2656 | J12: 6784 | K12: =IF(J13<>"",J13-J12,"") -> 422 | M12: =IF(L13<>"",L13-L12,"") | O12: =IF(N13<>"",N13-N12,"") | Q12: =IF(P13<>"",P13-P12,"") | R12: 16523 | S12: =IF(R13<>"",R13-R12,"") -> 640 | U12: =IF(T13<>"",T13-T12,"") | V12: 21467 | W12: =IF(V13<>"",V13-V12,"") -> 1345 | X12: 1996 | Y12: =IF(X13<>"",X13-X12,"") -> 422 | AJ12: =SUM(G12,K12,M12,O12,Q12,S12,U12,W12,Y12,AA12,AC12,AE12,AG12,AI12) -> 2829 | AK12: =(E12+I12)-AJ12 -> -173
B13: TUE | C13: 45846 | D13: 40635 | E13: =IF(D14<>"",D14-D13,"") -> 2071 | J13: 7206 | K13: =IF(J14<>"",J14-J13,"") -> 367 | M13: =IF(L14<>"",L14-L13,"") | O13: =IF(N14<>"",N14-N13,"") | Q13: =IF(P14<>"",P14-P13,"") | R13: 17163 | S13: =IF(R14<>"",R14-R13,"") -> 598 | U13: =IF(T14<>"",T14-T13,"") | V13: 22812 | W13: =IF(V14<>"",V14-V13,"") -> 1320 | X13: 2418 | Y13: =IF(X14<>"",X14-X13,"") -> 398 | AJ13: =SUM(G13,K13,M13,O13,Q13,S13,U13,W13,Y13,AA13,AC13,AE13,AG13,AI13) -> 2683 | AK13: =(E13+I13)-AJ13 -> -612
B14: WED | C14: 45847 | D14: 42706 | E14: =IF(D15<>"",D15-D14,"") -> 2567 | J14: 7573 | K14: =IF(J15<>"",J15-J14,"") -> 402 | M14: =IF(L15<>"",L15-L14,"") | O14: =IF(N15<>"",N15-N14,"") | Q14: =IF(P15<>"",P15-P14,"") | R14: 17761 | S14: =IF(R15<>"",R15-R14,"") -> 699 | U14: =IF(T15<>"",T15-T14,"") | V14: 24132 | W14: =IF(V15<>"",V15-V14,"") -> 1159 | X14: 2816 | Y14: =IF(X15<>"",X15-X14,"") -> 320 | AJ14: =SUM(G14,K14,M14,O14,Q14,S14,U14,W14,Y14,AA14,AC14,AE14,AG14,AI14) -> 2580 | AK14: =(E14+I14)-AJ14 -> -13
B15: THU | C15: 45848 | D15: 45273 | E15: =IF(D16<>"",D16-D15,"") -> 2403 | J15: 7975 | K15: =IF(J16<>"",J16-J15,"") -> 316 | M15: =IF(L16<>"",L16-L15,"") | O15: =IF(N16<>"",N16-N15,"") | Q15: =IF(P16<>"",P16-P15,"") | R15: 18460 | S15: =IF(R16<>"",R16-R15,"") -> 630 | U15: =IF(T16<>"",T16-T15,"") | V15: 25291 | W15: =IF(V16<>"",V16-V15,"") -> 1212 | X15: 3136 | Y15: =IF(X16<>"",X16-X15,"") -> 408 | AJ15: =SUM(G15,K15,M15,O15,Q15,S15,U15,W15,Y15,AA15,AC15,AE15,AG15,AI15) -> 2566 | AK15: =(E15+I15)-AJ15 -> -163
B16: FRI | C16: 45849 | D16: 47676 | E16: =IF(D17<>"",D17-D16,"") -> 2135 | J16: 8291 | K16: =IF(J17<>"",J17-J16,"") -> 412 | M16: =IF(L17<>"",L17-L16,"") | O16: =IF(N17<>"",N17-N16,"") | Q16: =IF(P17<>"",P17-P16,"") | R16: 19090 | S16: =IF(R17<>"",R17-R16,"") -> 757 | U16: =IF(T17<>"",T17-T16,"") | V16: 26503 | W16: =IF(V17<>"",V17-V16,"") -> 1358 | X16: 3544 | Y16: =IF(X17<>"",X17-X16,"") -> 418 | AJ16: =SUM(G16,K16,M16,O16,Q16,S16,U16,W16,Y16,AA16,AC16,AE16,AG16,AI16) -> 2945 | AK16: =(E16+I16)-AJ16 -> -810
B17: SAT | C17: 45850 | D17: 49811 | E17: =IF(D18<>"",D18-D17,"") -> 2866 | J17: 8703 | K17: =IF(J18<>"",J18-J17,"") -> 489 | M17: =IF(L18<>"",L18-L17,"") | O17: =IF(N18<>"",N18-N17,"") | Q17: =IF(P18<>"",P18-P17,"") | R17: 19847 | S17: =IF(R18<>"",R18-R17,"") -> 862 | U17: =IF(T18<>"",T18-T17,"") | V17: 27861 | W17: =IF(V18<>"",V18-V17,"") -> 1653 | X17: 3962 | Y17: =IF(X18<>"",X18-X17,"") -> 649 | AJ17: =SUM(G17,K17,M17,O17,Q17,S17,U17,W17,Y17,AA17,AC17,AE17,AG17,AI17) -> 3653 | AK17: =(E17+I17)-AJ17 -> -787
... B35: WED | C35: 45868 | D35: 99586 | E35: =IF(D36<>"",D36-D35,"") -> 3417 | J35: 15956 | K35: =IF(J36<>"",J36-J35,"") -> 608 | M35: =IF(L36<>"",L36-L35,"") | O35: =IF(N36<>"",N36-N35,"") | Q35: =IF(P36<>"",P36-P35,"") | R35: 30417 | S35: =IF(R36<>"",R36-R35,"") -> 832 | U35: =IF(T36<>"",T36-T35,"") | V35: 46681 | W35: =IF(V36<>"",V36-V35,"") -> 862 | X35: 13091 | Y35: =IF(X36<>"",X36-X35,"") -> 629 | AJ35: =SUM(G35,K35,M35,O35,Q35,S35,U35,W35,Y35,AA35,AC35,AE35,AG35,AI35) -> 2931 | AK35: =(E35+I35)-AJ35 -> 486
B36: THU | C36: 45869 | D36: 103003 | E36: =IF(D38<>"",D38-D36,"") -> 5178 | J36: 16564 | K36: =IF(J38<>"",J38-J36,"") -> 659 | M36: =IF(L38<>"",L38-L36,"") | O36: =IF(N38<>"",N38-N36,"") | Q36: =IF(P38<>"",P38-P36,"") | R36: 31249 | S36: =IF(R38<>"",R38-R36,"") -> 793 | U36: =IF(T38<>"",T38-T36,"") | V36: 47543 | W36: =IF(V38<>"",V38-V36,"") -> 949 | X36: 13720 | Y36: =IF(X38<>"",X38-X36,"") -> 603 | AJ36: =SUM(G36,K36,M36,O36,Q36,S36,U36,W36,Y36,AA36,AC36,AE36,AG36,AI36) -> 3004 | AK36: =(E36+I36)-AJ36 -> 2174
B37: kWh/Mo TTL | E37: =SUM(E4:E35) -> 73651 | K37: =SUM(K4:K35) -> 11243 | M37: =SUM(M4:M35) -> 0 | O37: =SUM(O4:O35) -> 0 | Q37: =SUM(Q4:Q35) -> 0 | S37: =SUM(S4:S35) -> 16836 | U37: =SUM(U4:U35) -> 0 | W37: =SUM(W4:W35) -> 30532 | Y37: =SUM(Y4:Y35) -> 13095 | AJ37: =SUM(U37,W37,Y37,AA37,AC37,AE37,AG37,AI37) -> 43627 | AK37: =AJ37-S37 -> 26791
B38: FRI | C38: 45870 | D38: 108181 | E38: =IF(D39<>"",D39-D38,"") -> 3075 | F38: 4880 | G38: =IF(F39<>"",F39-F38,"") -> 810 | H38: 79 | I38: =IF(H39<>"",H39-H38,"") -> 0 | J38: 17223 | K38: =IF(J39<>"",J39-J38,"") -> 594 | O38: =IF(N39<>"",N39-N38,"") -> 16291 | Q38: =IF(P39<>"",P39-P38,"") -> 4147 | R38: 32042 | S38: =IF(R39<>"",R39-R38,"") -> 945 | U38: =IF(T39<>"",T39-T38,"") -> 5741 | V38: 48492 | W38: =IF(V39<>"",V39-V38,"") -> 131 | X38: 14323 | Y38: =IF(X39<>"",X39-X38,"") -> 6087 | Z38: 78 | AA38: =IF(Z39<>"",Z39-Z38,"") -> 0 | AB38: 6850 | AC38: =IF(AB39<>"",AB39-AB38,"") -> 136 | AD38: 6754 | AE38: =IF(AD39<>"",AD39-AD38,"") -> 0 | AF38: 11429 | AG38: =IF(AF39<>"",AF39-AF38,"") -> 0 | AH38: 0 | AI38: =IF(AH39<>"",AH39-AH38,"") -> 571 | AJ38: =SUM(G38,K38,M38,O38,Q38,S38,U38,W38,Y38,AA38,AC38,AE38,AG38,AI38) -> 35453 | AK38: =(E38+I38)-AJ38 -> -32378
B39: SAT | C39: 45871 | D39: 111256 | E39: =IF(D40<>"",D40-D39,"") -> 1659 | F39: 5690 | G39: =IF(F40<>"",F40-F39,"") -> 934 | H39: 79 | I39: =IF(H40<>"",H40-H39,"") -> 1 | J39: 17817 | K39: =IF(J40<>"",J40-J39,"") -> 441 | L39: 2645 | M39: =IF(L40<>"",L40-L39,"") -> 62 | N39: 16291 | O39: =IF(N40<>"",N40-N39,"") -> 369 | P39: 4147 | Q39: =IF(P40<>"",P40-P39,"") -> 119 | R39: 32987 | S39: =IF(R40<>"",R40-R39,"") -> 703 | T39: 5741 | U39: =IF(T40<>"",T40-T39,"") -> 111 | V39: 48623 | W39: =IF(V40<>"",V40-V39,"") -> 11 | X39: 20410 | Y39: =IF(X40<>"",X40-X39,"") -> 617 | Z39: 78 | AA39: =IF(Z40<>"",Z40-Z39,"") -> 0 | AB39: 6986 | AC39: =IF(AB40<>"",AB40-AB39,"") -> 554 | AD39: 6754 | AE39: =IF(AD40<>"",AD40-AD39,"") -> 0 | AF39: 11429 | AG39: =IF(AF40<>"",AF40-AF39,"") -> 0 | AH39: 571 | AI39: =IF(AH40<>"",AH40-AH39,"") -> 673 | AJ39: =SUM(G39,K39,M39,O39,Q39,S39,U39,W39,Y39,AA39,AC39,AE39,AG39,AI39) -> 4594 | AK39: =(E39+I39)-AJ39 -> -2934
B40: SUN | C40: 45872 | D40: 112915 | E40: =IF(D41<>"",D41-D40,"") -> 0 | F40: 6624 | G40: =IF(F41<>"",F41-F40,"") -> 0 | H40: 80 | I40: =IF(H41<>"",H41-H40,"") -> 0 | J40: 18258 | K40: =IF(J41<>"",J41-J40,"") -> 0 | L40: 2707 | M40: =IF(L41<>"",L41-L40,"") -> 0 | N40: 16660 | O40: =IF(N41<>"",N41-N40,"") -> 0 | P40: 4266 | Q40: =IF(P41<>"",P41-P40,"") -> 0 | R40: 33690 | S40: =IF(R41<>"",R41-R40,"") -> 0 | T40: 5852 | U40: =IF(T41<>"",T41-T40,"") -> 0 | V40: 48634 | W40: =IF(V41<>"",V41-V40,"") -> 0 | X40: 21027 | Y40: =IF(X41<>"",X41-X40,"") -> 0 | Z40: 78 | AA40: =IF(Z41<>"",Z41-Z40,"") -> 0 | AB40: 7540 | AC40: =IF(AB41<>"",AB41-AB40,"") -> 0 | AD40: 6754 | AE40: =IF(AD41<>"",AD41-AD40,"") -> 0 | AF40: 11429 | AG40: =IF(AF41<>"",AF41-AF40,"") -> 0 | AH40: 1244 | AI40: =IF(AH41<>"",AH41-AH40,"") -> 0 | AJ40: =SUM(G40,K40,M40,O40,Q40,S40,U40,W40,Y40,AA40,AC40,AE40,AG40,AI40) -> 0 | AK40: =(E40+I40)-AJ40 -> 0
B41: MON | C41: 45873 | D41: 112915 | E41: =IF(D42<>"",D42-D41,"") -> 2748 | F41: 6624 | G41: =IF(F42<>"",F42-F41,"") -> 1047 | H41: 80 | I41: =IF(H42<>"",H42-H41,"") -> 0 | J41: 18258 | K41: =IF(J42<>"",J42-J41,"") -> 524 | L41: 2707 | M41: =IF(L42<>"",L42-L41,"") -> 69 | N41: 16660 | O41: =IF(N42<>"",N42-N41,"") -> 463 | P41: 4266 | Q41: =IF(P42<>"",P42-P41,"") -> 135 | R41: 33690 | S41: =IF(R42<>"",R42-R41,"") -> 757 | T41: 5852 | U41: =IF(T42<>"",T42-T41,"") -> 126 | V41: 48634 | W41: =IF(V42<>"",V42-V41,"") -> 2 | X41: 21027 | Y41: =IF(X42<>"",X42-X41,"") -> 696 | Z41: 78 | AA41: =IF(Z42<>"",Z42-Z41,"") -> 0 | AB41: 7540 | AC41: =IF(AB42<>"",AB42-AB41,"") -> 3 | AD41: 6754 | AE41: =IF(AD42<>"",AD42-AD41,"") -> 0 | AF41: 11429 | AG41: =IF(AF42<>"",AF42-AF41,"") -> 0 | AH41: 1244 | AI41: =IF(AH42<>"",AH42-AH41,"") -> 730 | AJ41: =SUM(G41,K41,M41,O41,Q41,S41,U41,W41,Y41,AA41,AC41,AE41,AG41,AI41) -> 4552 | AK41: =(E41+I41)-AJ41 -> -1804
B42: TUE | C42: 45874 | D42: 115663 | E42: =IF(D43<>"",D43-D42,"") -> 2036 | F42: 7671 | G42: =IF(F43<>"",F43-F42,"") -> 1163 | H42: 80 | I42: =IF(H43<>"",H43-H42,"") -> 0 | J42: 18782 | K42: =IF(J43<>"",J43-J42,"") -> 556 | L42: 2776 | M42: =IF(L43<>"",L43-L42,"") -> 67 | N42: 17123 | O42: =IF(N43<>"",N43-N42,"") -> 496 | P42: 4401 | Q42: =IF(P43<>"",P43-P42,"") -> 139 | R42: 34447 | S42: =IF(R43<>"",R43-R42,"") -> 672 | T42: 5978 | U42: =IF(T43<>"",T43-T42,"") -> 126 | V42: 48636 | W42: =IF(V43<>"",V43-V42,"") -> 2 | X42: 21723 | Y42: =IF(X43<>"",X43-X42,"") -> 707 | Z42: 78 | AA42: =IF(Z43<>"",Z43-Z42,"") -> 0 | AB42: 7543 | AC42: =IF(AB43<>"",AB43-AB42,"") -> 204 | AD42: 6754 | AE42: =IF(AD43<>"",AD43-AD42,"") -> 0 | AF42: 11429 | AG42: =IF(AF43<>"",AF43-AF42,"") -> 0 | AH42: 1974 | AI42: =IF(AH43<>"",AH43-AH42,"") -> 835 | AJ42: =SUM(G42,K42,M42,O42,Q42,S42,U42,W42,Y42,AA42,AC42,AE42,AG42,AI42) -> 4967 | AK42: =(E42+I42)-AJ42 -> -2931
B43: WED | C43: 45875 | D43: 117699 | E43: =IF(D44<>"",D44-D43,"") -> 2323 | F43: 8834 | G43: =IF(F44<>"",F44-F43,"") -> 1315 | H43: 80 | I43: =IF(H44<>"",H44-H43,"") -> 1 | J43: 19338 | K43: =IF(J44<>"",J44-J43,"") -> 568 | L43: 2843 | M43: =IF(L44<>"",L44-L43,"") -> 54 | N43: 17619 | O43: =IF(N44<>"",N44-N43,"") -> 450 | P43: 4540 | Q43: =IF(P44<>"",P44-P43,"") -> 134 | R43: 35119 | S43: =IF(R44<>"",R44-R43,"") -> 789 | T43: 6104 | U43: =IF(T44<>"",T44-T43,"") -> 117 | V43: 48638 | W43: =IF(V44<>"",V44-V43,"") -> 1 | X43: 22430 | Y43: =IF(X44<>"",X44-X43,"") -> 652 | Z43: 78 | AA43: =IF(Z44<>"",Z44-Z43,"") -> 0 | AB43: 7747 | AC43: =IF(AB44<>"",AB44-AB43,"") -> 198 | AD43: 6754 | AE43: =IF(AD44<>"",AD44-AD43,"") -> 0 | AF43: 11429 | AG43: =IF(AF44<>"",AF44-AF43,"") -> 0 | AH43: 2809 | AI43: =IF(AH44<>"",AH44-AH43,"") -> 805 | AJ43: =SUM(G43,K43,M43,O43,Q43,S43,U43,W43,Y43,AA43,AC43,AE43,AG43,AI43) -> 5083 | AK43: =(E43+I43)-AJ43 -> -2759
B44: THU | C44: 45876 | D44: 120022 | E44: =IF(D45<>"",D45-D44,"") -> 2689 | F44: 10149 | G44: =IF(F45<>"",F45-F44,"") -> 1313 | H44: 81 | I44: =IF(H45<>"",H45-H44,"") -> 0 | J44: 19906 | K44: =IF(J45<>"",J45-J44,"") -> 636 | L44: 2897 | M44: =IF(L45<>"",L45-L44,"") -> 65 | N44: 18069 | O44: =IF(N45<>"",N45-N44,"") -> 513 | P44: 4674 | Q44: =IF(P45<>"",P45-P44,"") -> 150 | R44: 35908 | S44: =IF(R45<>"",R45-R44,"") -> 821 | T44: 6221 | U44: =IF(T45<>"",T45-T44,"") -> 129 | V44: 48639 | W44: =IF(V45<>"",V45-V44,"") -> 0 | X44: 23082 | Y44: =IF(X45<>"",X45-X44,"") -> 751 | Z44: 78 | AA44: =IF(Z45<>"",Z45-Z44,"") -> 0 | AB44: 7945 | AC44: =IF(AB45<>"",AB45-AB44,"") -> 221 | AD44: 6754 | AE44: =IF(AD45<>"",AD45-AD44,"") -> 0 | AF44: 11429 | AG44: =IF(AF45<>"",AF45-AF44,"") -> 0 | AH44: 3614 | AI44: =IF(AH45<>"",AH45-AH44,"") -> 918 | AJ44: =SUM(G44,K44,M44,O44,Q44,S44,U44,W44,Y44,AA44,AC44,AE44,AG44,AI44) -> 5517 | AK44: =(E44+I44)-AJ44 -> -2828
B45: FRI | C45: 45877 | D45: 122711 | E45: =IF(D46<>"",D46-D45,"") -> 2081 | F45: 11462 | G45: =IF(F46<>"",F46-F45,"") -> 1102 | H45: 81 | I45: =IF(H46<>"",H46-H45,"") -> 0 | J45: 20542 | K45: =IF(J46<>"",J46-J45,"") -> 524 | L45: 2962 | M45: =IF(L46<>"",L46-L45,"") -> 64 | N45: 18582 | O45: =IF(N46<>"",N46-N45,"") -> 420 | P45: 4824 | Q45: =IF(P46<>"",P46-P45,"") -> 103 | R45: 36729 | S45: =IF(R46<>"",R46-R45,"") -> 691 | T45: 6350 | U45: =IF(T46<>"",T46-T45,"") -> 107 | V45: 48639 | W45: =IF(V46<>"",V46-V45,"") -> 0 | X45: 23833 | Y45: =IF(X46<>"",X46-X45,"") -> 600 | Z45: 78 | AA45: =IF(Z46<>"",Z46-Z45,"") -> 0 | AB45: 8166 | AC45: =IF(AB46<>"",AB46-AB45,"") -> 199 | AD45: 6754 | AE45: =IF(AD46<>"",AD46-AD45,"") -> 0 | AF45: 11429 | AG45: =IF(AF46<>"",AF46-AF45,"") -> 0 | AH45: 4532 | AI45: =IF(AH46<>"",AH46-AH45,"") -> 726 | AJ45: =SUM(G45,K45,M45,O45,Q45,S45,U45,W45,Y45,AA45,AC45,AE45,AG45,AI45) -> 4536 | AK45: =(E45+I45)-AJ45 -> -2455
B46: SAT | C46: 45878 | D46: 124792 | E46: =IF(D47<>"",D47-D46,"") -> 2096 | F46: 12564 | G46: =IF(F47<>"",F47-F46,"") -> 1131 | H46: 81 | I46: =IF(H47<>"",H47-H46,"") -> 0 | J46: 21066 | K46: =IF(J47<>"",J47-J46,"") -> 443 | L46: 3026 | M46: =IF(L47<>"",L47-L46,"") -> 48 | N46: 19002 | O46: =IF(N47<>"",N47-N46,"") -> 407 | P46: 4927 | Q46: =IF(P47<>"",P47-P46,"") -> 86 | R46: 37420 | S46: =IF(R47<>"",R47-R46,"") -> 723 | T46: 6457 | U46: =IF(T47<>"",T47-T46,"") -> 107 | V46: 48639 | W46: =IF(V47<>"",V47-V46,"") -> 0 | X46: 24433 | Y46: =IF(X47<>"",X47-X46,"") -> 625 | Z46: 78 | AA46: =IF(Z47<>"",Z47-Z46,"") -> 0 | AB46: 8365 | AC46: =IF(AB47<>"",AB47-AB46,"") -> 157 | AD46: 6754 | AE46: =IF(AD47<>"",AD47-AD46,"") -> 0 | AF46: 11429 | AG46: =IF(AF47<>"",AF47-AF46,"") -> 0 | AH46: 5258 | AI46: =IF(AH47<>"",AH47-AH46,"") -> 813 | AJ46: =SUM(G46,K46,M46,O46,Q46,S46,U46,W46,Y46,AA46,AC46,AE46,AG46,AI46) -> 4540 | AK46: =(E46+I46)-AJ46 -> -2444
B47: SUN | C47: 45879 | D47: 126888 | E47: =IF(D48<>"",D48-D47,"") -> 262 | F47: 13695 | G47: =IF(F48<>"",F48-F47,"") -> 58 | H47: 81 | I47: =IF(H48<>"",H48-H47,"") -> 1 | J47: 21509 | K47: =IF(J48<>"",J48-J47,"") -> 115 | L47: 3074 | M47: =IF(L48<>"",L48-L47,"") -> 13 | N47: 19409 | O47: =IF(N48<>"",N48-N47,"") -> 37 | P47: 5013 | Q47: =IF(P48<>"",P48-P47,"") -> 18 | R47: 38143 | S47: =IF(R48<>"",R48-R47,"") -> 37 | T47: 6564 | U47: =IF(T48<>"",T48-T47,"") -> 14 | V47: 48639 | W47: =IF(V48<>"",V48-V47,"") -> 0 | X47: 25058 | Y47: =IF(X48<>"",X48-X47,"") -> 28 | Z47: 78 | AA47: =IF(Z48<>"",Z48-Z47,"") -> 0 | AB47: 8522 | AC47: =IF(AB48<>"",AB48-AB47,"") -> 239 | AD47: 6754 | AE47: =IF(AD48<>"",AD48-AD47,"") -> 0 | AF47: 11429 | AG47: =IF(AF48<>"",AF48-AF47,"") -> 0 | AH47: 6071 | AI47: =IF(AH48<>"",AH48-AH47,"") -> 0 | AJ47: =SUM(G47,K47,M47,O47,Q47,S47,U47,W47,Y47,AA47,AC47,AE47,AG47,AI47) -> 559 | AK47: =(E47+I47)-AJ47 -> -296
B48: MON | C48: 45880 | D48: 127150 | E48: =IF(D49<>"",D49-D48,"") -> 2415 | F48: 13753 | G48: =IF(F49<>"",F49-F48,"") -> 1409 | H48: 82 | I48: =IF(H49<>"",H49-H48,"") -> 0 | J48: 21624 | K48: =IF(J49<>"",J49-J48,"") -> 548 | L48: 3087 | M48: =IF(L49<>"",L49-L48,"") -> 69 | N48: 19446 | O48: =IF(N49<>"",N49-N48,"") -> 474 | P48: 5031 | Q48: =IF(P49<>"",P49-P48,"") -> 115 | R48: 38180 | S48: =IF(R49<>"",R49-R48,"") -> 713 | T48: 6578 | U48: =IF(T49<>"",T49-T48,"") -> 140 | V48: 48639 | W48: =IF(V49<>"",V49-V48,"") -> 0 | X48: 25086 | Y48: =IF(X49<>"",X49-X48,"") -> 673 | Z48: 78 | AA48: =IF(Z49<>"",Z49-Z48,"") -> 0 | AB48: 8761 | AC48: =IF(AB49<>"",AB49-AB48,"") -> 211 | AD48: 6754 | AE48: =IF(AD49<>"",AD49-AD48,"") -> 0 | AF48: 11429 | AG48: =IF(AF49<>"",AF49-AF48,"") -> 0 | AH48: 6071 | AI48: =IF(AH49<>"",AH49-AH48,"") -> 954 | AJ48: =SUM(G48,K48,M48,O48,Q48,S48,U48,W48,Y48,AA48,AC48,AE48,AG48,AI48) -> 5306 | AK48: =(E48+I48)-AJ48 -> -2891
B49: TUE | C49: 45881 | D49: 129565 | E49: =IF(D50<>"",D50-D49,"") -> 2097 | F49: 15162 | G49: =IF(F50<>"",F50-F49,"") -> 1517 | H49: 82 | I49: =IF(H50<>"",H50-H49,"") -> 0 | J49: 22172 | K49: =IF(J50<>"",J50-J49,"") -> 535 | L49: 3156 | M49: =IF(L50<>"",L50-L49,"") -> 61 | N49: 19920 | O49: =IF(N50<>"",N50-N49,"") -> 448 | P49: 5146 | Q49: =IF(P50<>"",P50-P49,"") -> 133 | R49: 38893 | S49: =IF(R50<>"",R50-R49,"") -> 679 | T49: 6718 | U49: =IF(T50<>"",T50-T49,"") -> 102 | V49: 48639 | W49: =IF(V50<>"",V50-V49,"") -> 0 | X49: 25759 | Y49: =IF(X50<>"",X50-X49,"") -> 634 | Z49: 78 | AA49: =IF(Z50<>"",Z50-Z49,"") -> 1 | AB49: 8972 | AC49: =IF(AB50<>"",AB50-AB49,"") -> 191 | AD49: 6754 | AE49: =IF(AD50<>"",AD50-AD49,"") -> 0 | AF49: 11429 | AG49: =IF(AF50<>"",AF50-AF49,"") -> 0 | AH49: 7025 | AI49: =IF(AH50<>"",AH50-AH49,"") -> 816 | AJ49: =SUM(G49,K49,M49,O49,Q49,S49,U49,W49,Y49,AA49,AC49,AE49,AG49,AI49) -> 5117 | AK49: =(E49+I49)-AJ49 -> -3020
B50: WED | C50: 45882 | D50: 131662 | E50: =IF(D51<>"",D51-D50,"") -> 5885 | F50: 16679 | G50: =IF(F51<>"",F51-F50,"") -> 1562 | H50: 82 | I50: =IF(H51<>"",H51-H50,"") -> 1 | J50: 22707 | K50: =IF(J51<>"",J51-J50,"") -> 620 | L50: 3217 | M50: =IF(L51<>"",L51-L50,"") -> 86 | N50: 20368 | O50: =IF(N51<>"",N51-N50,"") -> 592 | P50: 5279 | Q50: =IF(P51<>"",P51-P50,"") -> 154 | R50: 39572 | S50: =IF(R51<>"",R51-R50,"") -> 729 | T50: 6820 | U50: =IF(T51<>"",T51-T50,"") -> 126 | V50: 48639 | W50: =IF(V51<>"",V51-V50,"") -> 0 | X50: 26393 | Y50: =IF(X51<>"",X51-X50,"") -> 816 | Z50: 79 | AA50: =IF(Z51<>"",Z51-Z50,"") -> 0 | AB50: 9163 | AC50: =IF(AB51<>"",AB51-AB50,"") -> 142 | AD50: 6754 | AE50: =IF(AD51<>"",AD51-AD50,"") -> 0 | AF50: 11429 | AG50: =IF(AF51<>"",AF51-AF50,"") -> 0 | AH50: 7841 | AI50: =IF(AH51<>"",AH51-AH50,"") -> 781 | AJ50: =SUM(G50,K50,M50,O50,Q50,S50,U50,W50,Y50,AA50,AC50,AE50,AG50,AI50) -> 5608 | AK50: =(E50+I50)-AJ50 -> 278
... B68: SUN | C68: 45900 | D68: 188463 | E68: =IF(D69<>"",D69-D68,"") -> 263 | F68: 41578 | G68: =IF(F69<>"",F69-F68,"") -> 19 | H68: 23890 | I68: =IF(H69<>"",H69-H68,"") -> 940 | J68: 32385 | K68: =IF(J69<>"",J69-J68,"") -> 306 | L68: 5179 | M68: =IF(L69<>"",L69-L68,"") -> 81 | N68: 27112 | O68: =IF(N69<>"",N69-N68,"") -> 38 | P68: 7515 | Q68: =IF(P69<>"",P69-P68,"") -> 16 | R68: 50159 | S68: =IF(R69<>"",R69-R68,"") -> 38 | T68: 9326 | U68: =IF(T69<>"",T69-T68,"") -> 16 | V68: 48639 | W68: =IF(V69<>"",V69-V68,"") -> 0 | X68: 36026 | Y68: =IF(X69<>"",X69-X68,"") -> 23 | Z68: 79 | AA68: =IF(Z69<>"",Z69-Z68,"") -> 0 | AB68: 11769 | AC68: =IF(AB69<>"",AB69-AB68,"") -> 89 | AD68: 6755 | AE68: =IF(AD69<>"",AD69-AD68,"") -> 0 | AF68: 11429 | AG68: =IF(AF69<>"",AF69-AF68,"") -> 0 | AH68: 19945 | AI68: =IF(AH69<>"",AH69-AH68,"") -> 37 | AJ68: =SUM(G68,K68,M68,O68,Q68,S68,U68,W68,Y68,AA68,AC68,AE68,AG68,AI68) -> 663 | AK68: =(E68+I68)-AJ68 -> 540
B69: MON | C69: 45901 | D69: 188726 | F69: 41597 | H69: 24830 | J69: 32691 | L69: 5260 | N69: 27150 | P69: 7531 | R69: 50197 | T69: 9342 | V69: 48639 | X69: 36049 | Z69: 79 | AB69: 11858 | AD69: 6755 | AF69: 11429 | AH69: 19982 | AJ69: =SUM(G69,K69,M69,O69,Q69,S69,U69,W69,Y69,AA69,AC69,AE69,AG69,AI69) -> 0 | AK69: =(E69+I69)-AJ69 -> 0
B70: kWh/Mo TTL | E70: =SUM(E38:E68) -> 80545 | G70: =SUM(G38:G68) -> 36717 | I70: =SUM(I38:I68) -> 24751 | K70: =SUM(K38:K68) -> 15468 | M70: =SUM(M38:M68) -> 2615 | O70: =SUM(O38:O68) -> 27150 | Q70: =SUM(Q38:Q68) -> 7531 | S70: =SUM(S38:S68) -> 18155 | U70: =SUM(U38:U68) -> 9342 | W70: =SUM(W38:W68) -> 147 | Y70: =SUM(Y38:Y68) -> 21726 | AA70: =SUM(AA38:AA68) -> 1 | AC70: =SUM(AC38:AC68) -> 5008 | AE70: =SUM(AE38:AE68) -> 1 | AG70: =SUM(AG38:AG68) -> 0 | AI70: =SUM(AI38:AI68) -> 19982 | AJ70: =SUM(G70,K70,M70,O70,Q70,S70,U70,W70,Y70,AA70,AC70,AE70,AG70,AI70) -> 163843 | AK70: =(E70+I70)-AJ70 -> -58547
B71: MON | C71: 45901 | D71: 188726 | E71: =IF(D72<>"",D72-D71,"") -> 3007 | F71: 41597 | G71: =IF(F72<>"",F72-F71,"") -> 1118 | H71: 24830 | I71: =IF(H72<>"",H72-H71,"") -> 1461 | J71: 32691 | K71: =IF(J72<>"",J72-J71,"") -> 468 | L71: 5260 | M71: =IF(L72<>"",L72-L71,"") -> 100 | N71: 27150 | O71: =IF(N72<>"",N72-N71,"") -> 425 | P71: 7531 | Q71: =IF(P72<>"",P72-P71,"") -> 114 | R71: 50197 | S71: =IF(R72<>"",R72-R71,"") -> 702 | T71: 9342 | U71: =IF(T72<>"",T72-T71,"") -> 147 | V71: 48639 | W71: =IF(V72<>"",V72-V71,"") -> 0 | X71: 36049 | Y71: =IF(X72<>"",X72-X71,"") -> 428 | Z71: 79 | AA71: =IF(Z72<>"",Z72-Z71,"") -> 0 | AB71: 11858 | AC71: =IF(AB72<>"",AB72-AB71,"") -> 95 | AD71: 6755 | AE71: =IF(AD72<>"",AD72-AD71,"") -> 0 | AF71: 11429 | AG71: =IF(AF72<>"",AF72-AF71,"") -> 0 | AH71: 19982 | AI71: =IF(AH72<>"",AH72-AH71,"") -> 667 | AJ71: =SUM(G71,K71,M71,O71,Q71,S71,U71,W71,Y71,AA71,AC71,AE71,AG71,AI71) -> 4264 | AK71: =(E71+I71)-AJ71 -> 204
B72: TUE | C72: 45902 | D72: 191733 | E72: =IF(D73<>"",D73-D72,"") -> 0 | F72: 42715 | G72: =IF(F73<>"",F73-F72,"") -> 1159 | H72: 26291 | I72: =IF(H73<>"",H73-H72,"") -> 1323 | J72: 33159 | K72: =IF(J73<>"",J73-J72,"") -> 509 | L72: 5360 | M72: =IF(L73<>"",L73-L72,"") -> 111 | N72: 27575 | O72: =IF(N73<>"",N73-N72,"") -> 430 | P72: 7645 | Q72: =IF(P73<>"",P73-P72,"") -> 111 | R72: 50899 | S72: =IF(R73<>"",R73-R72,"") -> 668 | T72: 9489 | U72: =IF(T73<>"",T73-T72,"") -> 127 | V72: 48639 | W72: =IF(V73<>"",V73-V72,"") -> 0 | X72: 36477 | Y72: =IF(X73<>"",X73-X72,"") -> 443 | Z72: 79 | AA72: =IF(Z73<>"",Z73-Z72,"") -> 0 | AB72: 11953 | AC72: =IF(AB73<>"",AB73-AB72,"") -> 97 | AD72: 6755 | AE72: =IF(AD73<>"",AD73-AD72,"") -> 0 | AF72: 11429 | AG72: =IF(AF73<>"",AF73-AF72,"") -> 0 | AH72: 20649 | AI72: =IF(AH73<>"",AH73-AH72,"") -> 783 | AJ72: =SUM(G72,K72,M72,O72,Q72,S72,U72,W72,Y72,AA72,AC72,AE72,AG72,AI72) -> 4438 | AK72: =(E72+I72)-AJ72 -> -3115
B73: WED | C73: 45903 | D73: 191733 | E73: =IF(D74<>"",D74-D73,"") -> 0 | F73: 43874 | G73: =IF(F74<>"",F74-F73,"") -> 1179 | H73: 27614 | I73: =IF(H74<>"",H74-H73,"") -> 2022 | J73: 33668 | K73: =IF(J74<>"",J74-J73,"") -> 544 | L73: 5471 | M73: =IF(L74<>"",L74-L73,"") -> 100 | N73: 28005 | O73: =IF(N74<>"",N74-N73,"") -> 374 | P73: 7756 | Q73: =IF(P74<>"",P74-P73,"") -> 109 | R73: 51567 | S73: =IF(R74<>"",R74-R73,"") -> 465 | T73: 9616 | U73: =IF(T74<>"",T74-T73,"") -> 143 | V73: 48639 | W73: =IF(V74<>"",V74-V73,"") -> 0 | X73: 36920 | Y73: =IF(X74<>"",X74-X73,"") -> 410 | Z73: 79 | AA73: =IF(Z74<>"",Z74-Z73,"") -> 0 | AB73: 12050 | AC73: =IF(AB74<>"",AB74-AB73,"") -> 99 | AD73: 6755 | AE73: =IF(AD74<>"",AD74-AD73,"") -> 0 | AF73: 11429 | AG73: =IF(AF74<>"",AF74-AF73,"") -> 0 | AH73: 21432 | AI73: =IF(AH74<>"",AH74-AH73,"") -> 657 | AJ73: =SUM(G73,K73,M73,O73,Q73,S73,U73,W73,Y73,AA73,AC73,AE73,AG73,AI73) -> 4080 | AK73: =(E73+I73)-AJ73 -> -2058
B74: THU | C74: 45904 | D74: 191733 | E74: =IF(D75<>"",D75-D74,"") -> 0 | F74: 45053 | G74: =IF(F75<>"",F75-F74,"") -> 1040 | H74: 29636 | I74: =IF(H75<>"",H75-H74,"") -> 2867 | J74: 34212 | K74: =IF(J75<>"",J75-J74,"") -> 589 | L74: 5571 | M74: =IF(L75<>"",L75-L74,"") -> 135 | N74: 28379 | O74: =IF(N75<>"",N75-N74,"") -> 413 | P74: 7865 | Q74: =IF(P75<>"",P75-P74,"") -> 121 | R74: 52032 | S74: =IF(R75<>"",R75-R74,"") -> 665 | T74: 9759 | U74: =IF(T75<>"",T75-T74,"") -> 153 | V74: 48639 | W74: =IF(V75<>"",V75-V74,"") -> 0 | X74: 37330 | Y74: =IF(X75<>"",X75-X74,"") -> 450 | Z74: 79 | AA74: =IF(Z75<>"",Z75-Z74,"") -> 0 | AB74: 12149 | AC74: =IF(AB75<>"",AB75-AB74,"") -> 118 | AD74: 6755 | AE74: =IF(AD75<>"",AD75-AD74,"") -> 0 | AF74: 11429 | AG74: =IF(AF75<>"",AF75-AF74,"") -> 0 | AH74: 22089 | AI74: =IF(AH75<>"",AH75-AH74,"") -> 687 | AJ74: =SUM(G74,K74,M74,O74,Q74,S74,U74,W74,Y74,AA74,AC74,AE74,AG74,AI74) -> 4371 | AK74: =(E74+I74)-AJ74 -> -1504
...

Sheet LT GF
A1: DENIM Ground Floor LT's ENERGY ANALYZER READINGS
A2: DAY | B2: DATE | C2: MAIN | E2: LT 01 GF | O2: MAIN | Q2: LT 02 GF | Y2: kWh/Day LT01 | Z2: kWh/Day LT02 | AA2: kWh/Day TTL | AB2: Diff. LT 01 | AC2: Diff. LT 02 | AD2: Diff. TTL
C3: 0 | E3: 1 | G3: 2 | I3: 3 | K3: 4 | M3: 5 | O3: 0 | Q3: 1 | S3: 2 | U3: 3 | W3: 4
C4: MPB-1-GF | E4: DB-EW-GF-M2 | G4: DB-EXAST FAN-GF | I4: DB-HVAC-GF1 | K4: DB-LP-HALL-1-GF | M4: DB-LP-OFFICE-1-GF | O4: MPB-2-GF2 | Q4: MCC-STICHING-GF | S4: DB-HVAC-GF2 | U4: DB-LP-HALL2-GF | W4: DB-LP-OFFICE-2-GF
C5: Meter Reading | D5: Daily Units (kWh) | E5: Meter Reading | F5: Daily Units (kWh) | G5: Meter Reading | H5: Daily Units (kWh) | I5: Meter Reading | J5: Daily Units (kWh) | K5: Meter Reading | L5: Daily Units (kWh) | M5: Meter Reading | N5: Daily Units (kWh) | O5: Meter Reading | P5: Daily Units (kWh) | Q5: Meter Reading | R5: Daily Units (kWh) | S5: Meter Reading | T5: Daily Units (kWh) | U5: Meter Reading | V5: Daily Units (kWh) | W5: Meter Reading | X5: Daily Units (kWh)
A6: TUE | B6: 45839 | C6: 5321 | D6: =IF(C7<>"",C7-C6,"") -> 363 | E6: 0 | F6: =IF(E7<>"",E7-E6,"") -> 0 | G6: 10 | H6: =IF(G7<>"",G7-G6,"") -> 33 | I6: 24 | J6: =IF(I7<>"",I7-I6,"") -> 10 | K6: 15 | L6: =IF(K7<>"",K7-K6,"") -> 35 | M6: 0 | N6: =IF(M7<>"",M7-M6,"") -> 0 | O6: 20 | P6: =IF(O7<>"",O7-O6,"") -> 81 | Q6: 0 | R6: =IF(Q7<>"",Q7-Q6,"") -> 0 | S6: 50 | T6: =IF(S7<>"",S7-S6,"") -> 50 | U6: 171 | V6: =IF(U7<>"",U7-U6,"") -> 101 | W6: 3 | X6: =IF(W7<>"",W7-W6,"") -> 3 | Y6: =SUM(F6,H6,J6,L6,N6) -> 78 | Z6: =SUM(R6,T6,V6,X6) -> 154 | AA6: =SUM(F6,H6,J6,L6,N6,R6,T6,V6,X6) -> 232 | AB6: =Y6-D6 -> -285 | AC6: =Z6-P6 -> 73 | AD6: =AA6-(D6+P6) -> -212
A7: WED | B7: 45840 | C7: 5684 | D7: =IF(C8<>"",C8-C7,"") -> 304 | E7: 0 | F7: =IF(E8<>"",E8-E7,"") -> 0 | G7: 43 | H7: =IF(G8<>"",G8-G7,"") -> 163 | I7: 34 | J7: =IF(I8<>"",I8-I7,"") -> 7 | K7: 50 | L7: =IF(K8<>"",K8-K7,"") -> 75 | M7: 0 | N7: =IF(M8<>"",M8-M7,"") -> 0 | O7: 101 | P7: =IF(O8<>"",O8-O7,"") -> 94 | Q7: 0 | R7: =IF(Q8<>"",Q8-Q7,"") -> 0 | S7: 100 | T7: =IF(S8<>"",S8-S7,"") -> 81 | U7: 272 | V7: =IF(U8<>"",U8-U7,"") -> 79 | W7: 6 | X7: =IF(W8<>"",W8-W7,"") -> 7 | Y7: =SUM(F7,H7,J7,L7,N7) -> 245 | Z7: =SUM(R7,T7,V7,X7) -> 167 | AA7: =SUM(F7,H7,J7,L7,N7,R7,T7,V7,X7) -> 412 | AB7: =Y7-D7 -> -59 | AC7: =Z7-P7 -> 73 | AD7: =AA7-(D7+P7) -> 14
A8: THU | B8: 45841 | C8: 5988 | D8: =IF(C9<>"",C9-C8,"") -> 376 | E8: 0 | F8: =IF(E9<>"",E9-E8,"") -> 0 | G8: 206 | H8: =IF(G9<>"",G9-G8,"") -> 197 | I8: 41 | J8: =IF(I9<>"",I9-I8,"") -> 10 | K8: 125 | L8: =IF(K9<>"",K9-K8,"") -> 90 | M8: 0 | N8: =IF(M9<>"",M9-M8,"") -> 0 | O8: 195 | P8: =IF(O9<>"",O9-O8,"") -> 200 | Q8: 0 | R8: =IF(Q9<>"",Q9-Q8,"") -> 0 | S8: 181 | T8: =IF(S9<>"",S9-S8,"") -> 75 | U8: 351 | V8: =IF(U9<>"",U9-U8,"") -> 95 | W8: 13 | X8: =IF(W9<>"",W9-W8,"") -> 8 | Y8: =SUM(F8,H8,J8,L8,N8) -> 297 | Z8: =SUM(R8,T8,V8,X8) -> 178 | AA8: =SUM(F8,H8,J8,L8,N8,R8,T8,V8,X8) -> 475 | AB8: =Y8-D8 -> -79 | AC8: =Z8-P8 -> -22 | AD8: =AA8-(D8+P8) -> -101
A9: FRI | B9: 45842 | C9: 6364 | D9: =IF(C10<>"",C10-C9,"") -> 195 | E9: 0 | F9: =IF(E10<>"",E10-E9,"") -> 0 | G9: 403 | H9: =IF(G10<>"",G10-G9,"") -> 89 | I9: 51 | J9: =IF(I10<>"",I10-I9,"") -> 5 | K9: 215 | L9: =IF(K10<>"",K10-K9,"") -> 70 | M9: 0 | N9: =IF(M10<>"",M10-M9,"") -> 0 | O9: 395 | P9: =IF(O10<>"",O10-O9,"") -> 106 | Q9: 0 | R9: =IF(Q10<>"",Q10-Q9,"") -> 0 | S9: 256 | T9: =IF(S10<>"",S10-S9,"") -> 45 | U9: 446 | V9: =IF(U10<>"",U10-U9,"") -> 49 | W9: 21 | X9: =IF(W10<>"",W10-W9,"") -> 10 | Y9: =SUM(F9,H9,J9,L9,N9) -> 164 | Z9: =SUM(R9,T9,V9,X9) -> 104 | AA9: =SUM(F9,H9,J9,L9,N9,R9,T9,V9,X9) -> 268 | AB9: =Y9-D9 -> -31 | AC9: =Z9-P9 -> -2 | AD9: =AA9-(D9+P9) -> -33
A10: SAT | B10: 45843 | C10: 6559 | D10: =IF(C11<>"",C11-C10,"") -> 225 | E10: 0 | F10: =IF(E11<>"",E11-E10,"") -> 0 | G10: 492 | H10: =IF(G11<>"",G11-G10,"") -> 145 | I10: 56 | J10: =IF(I11<>"",I11-I10,"") -> 5 | K10: 285 | L10: =IF(K11<>"",K11-K10,"") -> 19 | M10: 0 | N10: =IF(M11<>"",M11-M10,"") -> 1 | O10: 501 | P10: =IF(O11<>"",O11-O10,"") -> 118 | Q10: 0 | R10: =IF(Q11<>"",Q11-Q10,"") -> 0 | S10: 301 | T10: =IF(S11<>"",S11-S10,"") -> 51 | U10: 495 | V10: =IF(U11<>"",U11-U10,"") -> 36 | W10: 31 | X10: =IF(W11<>"",W11-W10,"") -> 6 | Y10: =SUM(F10,H10,J10,L10,N10) -> 170 | Z10: =SUM(R10,T10,V10,X10) -> 93 | AA10: =SUM(F10,H10,J10,L10,N10,R10,T10,V10,X10) -> 263 | AB10: =Y10-D10 -> -55 | AC10: =Z10-P10 -> -25 | AD10: =AA10-(D10+P10) -> -80
A11: SUN | B11: 45844 | C11: 6784 | D11: =IF(C12<>"",C12-C11,"") -> 0 | E11: 0 | F11: =IF(E12<>"",E12-E11,"") -> 0 | G11: 637 | H11: =IF(G12<>"",G12-G11,"") -> 0 | I11: 61 | J11: =IF(I12<>"",I12-I11,"") -> 0 | K11: 304 | L11: =IF(K12<>"",K12-K11,"") -> 0 | M11: 1 | N11: =IF(M12<>"",M12-M11,"") -> 0 | O11: 619 | P11: =IF(O12<>"",O12-O11,"") -> 0 | Q11: 0 | R11: =IF(Q12<>"",Q12-Q11,"") -> 0 | S11: 352 | T11: =IF(S12<>"",S12-S11,"") -> 0 | U11: 531 | V11: =IF(U12<>"",U12-U11,"") -> 0 | W11: 37 | X11: =IF(W12<>"",W12-W11,"") -> 0 | Y11: =SUM(F11,H11,J11,L11,N11) -> 0 | Z11: =SUM(R11,T11,V11,X11) -> 0 | AA11: =SUM(F11,H11,J11,L11,N11,R11,T11,V11,X11) -> 0 | AB11: =Y11-D11 -> 0 | AC11: =Z11-P11 -> 0 | AD11: =AA11-(D11+P11) -> 0
A12: MON | B12: 45845 | C12: 6784 | D12: =IF(C13<>"",C13-C12,"") -> 422 | E12: 0 | F12: =IF(E13<>"",E13-E12,"") -> 0 | G12: 637 | H12: =IF(G13<>"",G13-G12,"") -> 231 | I12: 61 | J12: =IF(I13<>"",I13-I12,"") -> 13 | K12: 304 | L12: =IF(K13<>"",K13-K12,"") -> 83 | M12: 1 | N12: =IF(M13<>"",M13-M12,"") -> 0 | O12: 619 | P12: =IF(O13<>"",O13-O12,"") -> 203 | Q12: 0 | R12: =IF(Q13<>"",Q13-Q12,"") -> 0 | S12: 352 | T12: =IF(S13<>"",S13-S12,"") -> 87 | U12: 531 | V12: =IF(U13<>"",U13-U12,"") -> 89 | W12: 37 | X12: =IF(W13<>"",W13-W12,"") -> 6 | Y12: =SUM(F12,H12,J12,L12,N12) -> 327 | Z12: =SUM(R12,T12,V12,X12) -> 182 | AA12: =SUM(F12,H12,J12,L12,N12,R12,T12,V12,X12) -> 509 | AB12: =Y12-D12 -> -95 | AC12: =Z12-P12 -> -21 | AD12: =AA12-(D12+P12) -> -116
A13: TUE | B13: 45846 | C13: 7206 | D13: =IF(C14<>"",C14-C13,"") -> 367 | E13: 0 | F13: =IF(E14<>"",E14-E13,"") -> 0 | G13: 868 | H13: =IF(G14<>"",G14-G13,"") -> 191 | I13: 74 | J13: =IF(I14<>"",I14-I13,"") -> 11 | K13: 387 | L13: =IF(K14<>"",K14-K13,"") -> 80 | M13: 1 | N13: =IF(M14<>"",M14-M13,"") -> 0 | O13: 822 | P13: =IF(O14<>"",O14-O13,"") -> 153 | Q13: 0 | R13: =IF(Q14<>"",Q14-Q13,"") -> 0 | S13: 439 | T13: =IF(S14<>"",S14-S13,"") -> 58 | U13: 620 | V13: =IF(U14<>"",U14-U13,"") -> 75 | W13: 43 | X13: =IF(W14<>"",W14-W13,"") -> 7 | Y13: =SUM(F13,H13,J13,L13,N13) -> 282 | Z13: =SUM(R13,T13,V13,X13) -> 140 | AA13: =SUM(F13,H13,J13,L13,N13,R13,T13,V13,X13) -> 422 | AB13: =Y13-D13 -> -85 | AC13: =Z13-P13 -> -13 | AD13: =AA13-(D13+P13) -> -98
A14: WED | B14: 45847 | C14: 7573 | D14: =IF(C15<>"",C15-C14,"") -> 402 | E14: 0 | F14: =IF(E15<>"",E15-E14,"") -> 0 | G14: 1059 | H14: =IF(G15<>"",G15-G14,"") -> 191 | I14: 85 | J14: =IF(I15<>"",I15-I14,"") -> 10 | K14: 467 | L14: =IF(K15<>"",K15-K14,"") -> 96 | M14: 1 | N14: =IF(M15<>"",M15-M14,"") -> 0 | O14: 975 | P14: =IF(O15<>"",O15-O14,"") -> 146 | Q14: 0 | R14: =IF(Q15<>"",Q15-Q14,"") -> 0 | S14: 497 | T14: =IF(S15<>"",S15-S14,"") -> 59 | U14: 695 | V14: =IF(U15<>"",U15-U14,"") -> 114 | W14: 50 | X14: =IF(W15<>"",W15-W14,"") -> 7 | Y14: =SUM(F14,H14,J14,L14,N14) -> 297 | Z14: =SUM(R14,T14,V14,X14) -> 180 | AA14: =SUM(F14,H14,J14,L14,N14,R14,T14,V14,X14) -> 477 | AB14: =Y14-D14 -> -105 | AC14: =Z14-P14 -> 34 | AD14: =AA14-(D14+P14) -> -71
A15: THU | B15: 45848 | C15: 7975 | D15: =IF(C16<>"",C16-C15,"") -> 316 | E15: 0 | F15: =IF(E16<>"",E16-E15,"") -> 0 | G15: 1250 | H15: =IF(G16<>"",G16-G15,"") -> 157 | I15: 95 | J15: =IF(I16<>"",I16-I15,"") -> 1 | K15: 563 | L15: =IF(K16<>"",K16-K15,"") -> 66 | M15: 1 | N15: =IF(M16<>"",M16-M15,"") -> 1 | O15: 1121 | P15: =IF(O16<>"",O16-O15,"") -> 165 | Q15: 0 | R15: =IF(Q16<>"",Q16-Q15,"") -> 0 | S15: 556 | T15: =IF(S16<>"",S16-S15,"") -> 37 | U15: 809 | V15: =IF(U16<>"",U16-U15,"") -> 71 | W15: 57 | X15: =IF(W16<>"",W16-W15,"") -> 8 | Y15: =SUM(F15,H15,J15,L15,N15) -> 225 | Z15: =SUM(R15,T15,V15,X15) -> 116 | AA15: =SUM(F15,H15,J15,L15,N15,R15,T15,V15,X15) -> 341 | AB15: =Y15-D15 -> -91 | AC15: =Z15-P15 -> -49 | AD15: =AA15-(D15+P15) -> -140
A16: FRI | B16: 45849 | C16: 8291 | D16: =IF(C17<>"",C17-C16,"") -> 412 | E16: 0 | F16: =IF(E17<>"",E17-E16,"") -> 0 | G16: 1407 | H16: =IF(G17<>"",G17-G16,"") -> 219 | I16: 96 | J16: =IF(I17<>"",I17-I16,"") -> 5 | K16: 629 | L16: =IF(K17<>"",K17-K16,"") -> 84 | M16: 2 | N16: =IF(M17<>"",M17-M16,"") -> 1 | O16: 1286 | P16: =IF(O17<>"",O17-O16,"") -> 214 | Q16: 0 | R16: =IF(Q17<>"",Q17-Q16,"") -> 0 | S16: 593 | T16: =IF(S17<>"",S17-S16,"") -> 60 | U16: 880 | V16: =IF(U17<>"",U17-U16,"") -> 125 | W16: 65 | X16: =IF(W17<>"",W17-W16,"") -> 8 | Y16: =SUM(F16,H16,J16,L16,N16) -> 309 | Z16: =SUM(R16,T16,V16,X16) -> 193 | AA16: =SUM(F16,H16,J16,L16,N16,R16,T16,V16,X16) -> 502 | AB16: =Y16-D16 -> -103 | AC16: =Z16-P16 -> -21 | AD16: =AA16-(D16+P16) -> -124
A17: SAT | B17: 45850 | C17: 8703 | D17: =IF(C18<>"",C18-C17,"") -> 489 | E17: 0 | F17: =IF(E18<>"",E18-E17,"") -> 0 | G17: 1626 | H17: =IF(G18<>"",G18-G17,"") -> 245 | I17: 101 | J17: =IF(I18<>"",I18-I17,"") -> 9 | K17: 713 | L17: =IF(K18<>"",K18-K17,"") -> 96 | M17: 3 | N17: =IF(M18<>"",M18-M17,"") -> 0 | O17: 1500 | P17: =IF(O18<>"",O18-O17,"") -> 231 | Q17: 0 | R17: =IF(Q18<>"",Q18-Q17,"") -> 0 | S17: 653 | T17: =IF(S18<>"",S18-S17,"") -> 73 | U17: 1005 | V17: =IF(U18<>"",U18-U17,"") -> 94 | W17: 73 | X17: =IF(W18<>"",W18-W17,"") -> 6 | Y17: =SUM(F17,H17,J17,L17,N17) -> 350 | Z17: =SUM(R17,T17,V17,X17) -> 173 | AA17: =SUM(F17,H17,J17,L17,N17,R17,T17,V17,X17) -> 523 | AB17: =Y17-D17 -> -139 | AC17: =Z17-P17 -> -58 | AD17: =AA17-(D17+P17) -> -197
... A35: WED | B35: 45868 | C35: 15956 | D35: =IF(C36<>"",C36-C35,"") -> 608 | E35: 0 | F35: =IF(E36<>"",E36-E35,"") -> 0 | G35: 4958 | H35: =IF(G36<>"",G36-G35,"") -> 253 | I35: 268 | J35: =IF(I36<>"",I36-I35,"") -> 14 | K35: 2458 | L35: =IF(K36<>"",K36-K35,"") -> 112 | M35: 22 | N35: =IF(M36<>"",M36-M35,"") -> 1 | O35: 4467 | P35: =IF(O36<>"",O36-O35,"") -> 206 | Q35: 0 | R35: =IF(Q36<>"",Q36-Q35,"") -> 0 | S35: 1701 | T35: =IF(S36<>"",S36-S35,"") -> 81 | U35: 2466 | V35: =IF(U36<>"",U36-U35,"") -> 78 | W35: 254 | X35: =IF(W36<>"",W36-W35,"") -> 10 | Y35: =SUM(F35,H35,J35,L35,N35) -> 380 | Z35: =SUM(R35,T35,V35,X35) -> 169 | AA35: =SUM(F35,H35,J35,L35,N35,R35,T35,V35,X35) -> 549 | AB35: =Y35-D35 -> -228 | AC35: =Z35-P35 -> -37 | AD35: =AA35-(D35+P35) -> -265
A36: THU | B36: 45869 | C36: 16564 | D36: =IF(C38<>"",C38-C36,"") -> 659 | E36: 0 | F36: =IF(E38<>"",E38-E36,"") -> 0 | G36: 5211 | H36: =IF(G38<>"",G38-G36,"") -> 284 | I36: 282 | J36: =IF(I38<>"",I38-I36,"") -> 5 | K36: 2570 | L36: =IF(K38<>"",K38-K36,"") -> 117 | M36: 23 | N36: =IF(M38<>"",M38-M36,"") -> 1 | O36: 4673 | P36: =IF(O38<>"",O38-O36,"") -> 183 | Q36: 0 | R36: =IF(Q38<>"",Q38-Q36,"") -> 0 | S36: 1782 | T36: =IF(S38<>"",S38-S36,"") -> 79 | U36: 2544 | V36: =IF(U38<>"",U38-U36,"") -> 89 | W36: 264 | X36: =IF(W38<>"",W38-W36,"") -> 12 | Y36: =SUM(F36,H36,J36,L36,N36) -> 407 | Z36: =SUM(R36,T36,V36,X36) -> 180 | AA36: =SUM(F36,H36,J36,L36,N36,R36,T36,V36,X36) -> 587 | AB36: =Y36-D36 -> -252 | AC36: =Z36-P36 -> -3 | AD36: =AA36-(D36+P36) -> -255
A37: kWh/Mo TTL | D37: =SUM(D4:D35) -> 11243 | F37: =SUM(F4:F35) -> 0 | H37: =SUM(H4:H35) -> 5201 | J37: =SUM(J4:J35) -> 258 | L37: =SUM(L4:L35) -> 2555 | N37: =SUM(N4:N35) -> 23 | P37: =SUM(P4:P35) -> 4653 | R37: =SUM(R4:R35) -> 0 | T37: =SUM(T4:T35) -> 1732 | V37: =SUM(V4:V35) -> 2373 | X37: =SUM(X4:X35) -> 261 | Y37: =SUM(F37,H37,J37,L37,N37) -> 8037 | Z37: =SUM(R37,T37,V37,X37) -> 4366 | AA37: =SUM(F37,H37,J37,L37,N37,R37,T37,V37,X37) -> 12403 | AB37: =Y37-D37 -> -3206 | AC37: =Z37-P37 -> -287 | AD37: =AA37-(D37+P37) -> -3493
A38: FRI | B38: 45870 | C38: 17223 | D38: =IF(C39<>"",C39-C38,"") -> 429 | E38: 0 | F38: =IF(E39<>"",E39-E38,"") -> 0 | G38: 5495 | H38: =IF(G39<>"",G39-G38,"") -> 217 | I38: 287 | J38: =IF(I39<>"",I39-I38,"") -> 0 | K38: 2687 | L38: =IF(K39<>"",K39-K38,"") -> 82 | M38: 24 | N38: =IF(M39<>"",M39-M38,"") -> 1 | O38: 4856 | P38: =IF(O39<>"",O39-O38,"") -> 165 | Q38: 0 | R38: =IF(Q39<>"",Q39-Q38,"") -> 0 | S38: 1861 | T38: =IF(S39<>"",S39-S38,"") -> 70 | U38: 2633 | V38: =IF(U39<>"",U39-U38,"") -> 71 | W38: 276 | X38: =IF(W39<>"",W39-W38,"") -> 10 | Y38: =SUM(F38,H38,J38,L38,N38) -> 300 | Z38: =SUM(R38,T38,V38,X38) -> 151 | AA38: =SUM(F38,H38,J38,L38,N38,R38,T38,V38,X38) -> 451 | AB38: =Y38-D38 -> -129 | AC38: =Z38-P38 -> -14 | AD38: =AA38-(D38+P38) -> -143
A39: SAT | B39: 45871 | C39: 17652 | D39: =IF(C40<>"",C40-C39,"") -> 441 | E39: 0 | F39: =IF(E40<>"",E40-E39,"") -> 0 | G39: 5712 | H39: =IF(G40<>"",G40-G39,"") -> 191 | I39: 287 | J39: =IF(I40<>"",I40-I39,"") -> 5 | K39: 2769 | L39: =IF(K40<>"",K40-K39,"") -> 83 | M39: 25 | N39: =IF(M40<>"",M40-M39,"") -> 1 | O39: 5021 | P39: =IF(O40<>"",O40-O39,"") -> 158 | Q39: 0 | R39: =IF(Q40<>"",Q40-Q39,"") -> 0 | S39: 1931 | T39: =IF(S40<>"",S40-S39,"") -> 67 | U39: 2704 | V39: =IF(U40<>"",U40-U39,"") -> 56 | W39: 286 | X39: =IF(W40<>"",W40-W39,"") -> 10 | Y39: =SUM(F39,H39,J39,L39,N39) -> 280 | Z39: =SUM(R39,T39,V39,X39) -> 133 | AA39: =SUM(F39,H39,J39,L39,N39,R39,T39,V39,X39) -> 413 | AB39: =Y39-D39 -> -161 | AC39: =Z39-P39 -> -25 | AD39: =AA39-(D39+P39) -> -186
A40: SUN | B40: 45872 | C40: 18093 | D40: =IF(C41<>"",C41-C40,"") -> 0 | E40: 0 | F40: =IF(E41<>"",E41-E40,"") -> 0 | G40: 5903 | H40: =IF(G41<>"",G41-G40,"") -> 0 | I40: 292 | J40: =IF(I41<>"",I41-I40,"") -> 0 | K40: 2852 | L40: =IF(K41<>"",K41-K40,"") -> 0 | M40: 26 | N40: =IF(M41<>"",M41-M40,"") -> 0 | O40: 5179 | P40: =IF(O41<>"",O41-O40,"") -> 0 | Q40: 0 | R40: =IF(Q41<>"",Q41-Q40,"") -> 0 | S40: 1998 | T40: =IF(S41<>"",S41-S40,"") -> 0 | U40: 2760 | V40: =IF(U41<>"",U41-U40,"") -> 0 | W40: 296 | X40: =IF(W41<>"",W41-W40,"") -> 0 | Y40: =SUM(F40,H40,J40,L40,N40) -> 0 | Z40: =SUM(R40,T40,V40,X40) -> 0 | AA40: =SUM(F40,H40,J40,L40,N40,R40,T40,V40,X40) -> 0 | AB40: =Y40-D40 -> 0 | AC40: =Z40-P40 -> 0 | AD40: =AA40-(D40+P40) -> 0
A41: MON | B41: 45873 | C41: 18093 | D41: =IF(C42<>"",C42-C41,"") -> 505 | E41: 0 | F41: =IF(E42<>"",E42-E41,"") -> 0 | G41: 5903 | H41: =IF(G42<>"",G42-G41,"") -> 205 | I41: 292 | J41: =IF(I42<>"",I42-I41,"") -> 8 | K41: 2852 | L41: =IF(K42<>"",K42-K41,"") -> 85 | M41: 26 | N41: =IF(M42<>"",M42-M41,"") -> 2 | O41: 5179 | P41: =IF(O42<>"",O42-O41,"") -> 192 | Q41: 0 | R41: =IF(Q42<>"",Q42-Q41,"") -> 3 | S41: 1998 | T41: =IF(S42<>"",S42-S41,"") -> 91 | U41: 2760 | V41: =IF(U42<>"",U42-U41,"") -> 63 | W41: 296 | X41: =IF(W42<>"",W42-W41,"") -> 13 | Y41: =SUM(F41,H41,J41,L41,N41) -> 300 | Z41: =SUM(R41,T41,V41,X41) -> 170 | AA41: =SUM(F41,H41,J41,L41,N41,R41,T41,V41,X41) -> 470 | AB41: =Y41-D41 -> -205 | AC41: =Z41-P41 -> -22 | AD41: =AA41-(D41+P41) -> -227
A42: TUE | B42: 45874 | C42: 18598 | D42: =IF(C43<>"",C43-C42,"") -> 555 | E42: 0 | F42: =IF(E43<>"",E43-E42,"") -> 0 | G42: 6108 | H42: =IF(G43<>"",G43-G42,"") -> 214 | I42: 300 | J42: =IF(I43<>"",I43-I42,"") -> 11 | K42: 2937 | L42: =IF(K43<>"",K43-K42,"") -> 91 | M42: 28 | N42: =IF(M43<>"",M43-M42,"") -> 8 | O42: 5371 | P42: =IF(O43<>"",O43-O42,"") -> 176 | Q42: 3 | R42: =IF(Q43<>"",Q43-Q42,"") -> 0 | S42: 2089 | T42: =IF(S43<>"",S43-S42,"") -> 73 | U42: 2823 | V42: =IF(U43<>"",U43-U42,"") -> 66 | W42: 309 | X42: =IF(W43<>"",W43-W42,"") -> 10 | Y42: =SUM(F42,H42,J42,L42,N42) -> 324 | Z42: =SUM(R42,T42,V42,X42) -> 149 | AA42: =SUM(F42,H42,J42,L42,N42,R42,T42,V42,X42) -> 473 | AB42: =Y42-D42 -> -231 | AC42: =Z42-P42 -> -27 | AD42: =AA42-(D42+P42) -> -258
A43: WED | B43: 45875 | C43: 19153 | D43: =IF(C44<>"",C44-C43,"") -> 571 | E43: 0 | F43: =IF(E44<>"",E44-E43,"") -> 0 | G43: 6322 | H43: =IF(G44<>"",G44-G43,"") -> 199 | I43: 311 | J43: =IF(I44<>"",I44-I43,"") -> 21 | K43: 3028 | L43: =IF(K44<>"",K44-K43,"") -> 96 | M43: 36 | N43: =IF(M44<>"",M44-M43,"") -> 7 | O43: 5547 | P43: =IF(O44<>"",O44-O43,"") -> 156 | Q43: 3 | R43: =IF(Q44<>"",Q44-Q43,"") -> 2 | S43: 2162 | T43: =IF(S44<>"",S44-S43,"") -> 74 | U43: 2889 | V43: =IF(U44<>"",U44-U43,"") -> 62 | W43: 319 | X43: =IF(W44<>"",W44-W43,"") -> 15 | Y43: =SUM(F43,H43,J43,L43,N43) -> 323 | Z43: =SUM(R43,T43,V43,X43) -> 153 | AA43: =SUM(F43,H43,J43,L43,N43,R43,T43,V43,X43) -> 476 | AB43: =Y43-D43 -> -248 | AC43: =Z43-P43 -> -3 | AD43: =AA43-(D43+P43) -> -251
A44: THU | B44: 45876 | C44: 19724 | D44: =IF(C45<>"",C45-C44,"") -> 666 | E44: 0 | F44: =IF(E45<>"",E45-E44,"") -> 0 | G44: 6521 | H44: =IF(G45<>"",G45-G44,"") -> 241 | I44: 332 | J44: =IF(I45<>"",I45-I44,"") -> 33 | K44: 3124 | L44: =IF(K45<>"",K45-K44,"") -> 96 | M44: 43 | N44: =IF(M45<>"",M45-M44,"") -> 1 | O44: 5703 | P44: =IF(O45<>"",O45-O44,"") -> 199 | Q44: 5 | R44: =IF(Q45<>"",Q45-Q44,"") -> 3 | S44: 2236 | T44: =IF(S45<>"",S45-S44,"") -> 80 | U44: 2951 | V44: =IF(U45<>"",U45-U44,"") -> 67 | W44: 334 | X44: =IF(W45<>"",W45-W44,"") -> 14 | Y44: =SUM(F44,H44,J44,L44,N44) -> 371 | Z44: =SUM(R44,T44,V44,X44) -> 164 | AA44: =SUM(F44,H44,J44,L44,N44,R44,T44,V44,X44) -> 535 | AB44: =Y44-D44 -> -295 | AC44: =Z44-P44 -> -35 | AD44: =AA44-(D44+P44) -> -330
A45: FRI | B45: 45877 | C45: 20390 | D45: =IF(C46<>"",C46-C45,"") -> 487 | E45: 0 | F45: =IF(E46<>"",E46-E45,"") -> 0 | G45: 6762 | H45: =IF(G46<>"",G46-G45,"") -> 186 | I45: 365 | J45: =IF(I46<>"",I46-I45,"") -> 43 | K45: 3220 | L45: =IF(K46<>"",K46-K45,"") -> 76 | M45: 44 | N45: =IF(M46<>"",M46-M45,"") -> 1 | O45: 5902 | P45: =IF(O46<>"",O46-O45,"") -> 171 | Q45: 8 | R45: =IF(Q46<>"",Q46-Q45,"") -> 18 | S45: 2316 | T45: =IF(S46<>"",S46-S45,"") -> 72 | U45: 3018 | V45: =IF(U46<>"",U46-U45,"") -> 46 | W45: 348 | X45: =IF(W46<>"",W46-W45,"") -> 11 | Y45: =SUM(F45,H45,J45,L45,N45) -> 306 | Z45: =SUM(R45,T45,V45,X45) -> 147 | AA45: =SUM(F45,H45,J45,L45,N45,R45,T45,V45,X45) -> 453 | AB45: =Y45-D45 -> -181 | AC45: =Z45-P45 -> -24 | AD45: =AA45-(D45+P45) -> -205
A46: SAT | B46: 45878 | C46: 20877 | D46: =IF(C47<>"",C47-C46,"") -> 519 | E46: 0 | F46: =IF(E47<>"",E47-E46,"") -> 0 | G46: 6948 | H46: =IF(G47<>"",G47-G46,"") -> 199 | I46: 408 | J46: =IF(I47<>"",I47-I46,"") -> 10 | K46: 3296 | L46: =IF(K47<>"",K47-K46,"") -> 80 | M46: 45 | N46: =IF(M47<>"",M47-M46,"") -> 4 | O46: 6073 | P46: =IF(O47<>"",O47-O46,"") -> 152 | Q46: 26 | R46: =IF(Q47<>"",Q47-Q46,"") -> 0 | S46: 2388 | T46: =IF(S47<>"",S47-S46,"") -> 61 | U46: 3064 | V46: =IF(U47<>"",U47-U46,"") -> 55 | W46: 359 | X46: =IF(W47<>"",W47-W46,"") -> 7 | Y46: =SUM(F46,H46,J46,L46,N46) -> 293 | Z46: =SUM(R46,T46,V46,X46) -> 123 | AA46: =SUM(F46,H46,J46,L46,N46,R46,T46,V46,X46) -> 416 | AB46: =Y46-D46 -> -226 | AC46: =Z46-P46 -> -29 | AD46: =AA46-(D46+P46) -> -255
